Workbook
Name V2_ValuePerShare: 'DCF Valuation'!$E$40
Name V2_WACC: 'DCF Valuation'!$E$15
Name V2_Scenario: 'Assumptions'!$C$4

Sheet Assumptions
A1: BSE Ltd — Assumptions, Drivers & Scenario Manager
A2: Yellow cells are editable. Base/Bear/Bull are typed inputs; the ACTIVE column resolves the selected scenario and is the ONLY column downstream tabs reference. Driver architecture follows management's own statement: revenue on premium, SEBI levy on notional, clearing on contracts.
A3: Units: Rs Crore. Percentages stored as decimals. Realisation = Rs cr of charges per Rs cr of ADT.
A4: SCENARIO (1 = Base · 2 = Bear · 3 = Bull) | C4: 1 | E4: <- change this one cell to switch the whole model
A6: Driver | B6: FY24 | C6: FY25 | D6: FY26 | E6: Base | F6: Bear | G6: Bull | H6: ACTIVE | I6: Source / basis
A7: DRIVER 1 — index-options PREMIUM ADT (revenue rides this)
A8: Premium ADT growth — FY27E (%) | E8: 0.35 | F8: 0 | G8: 0.6 | H8: =CHOOSE($C$4,E8,F8,G8) | I8: Applied to the FY26 AVERAGE of Rs19,523cr. Base +35% -> Rs26,356cr, which is still 11% BELOW the Q1FY27 actual of Rs29,615cr, so the base is NOT aggressive on this driver. WARNING on the bear: 0% holds FY27E at the FY26 average, which is a 34% FALL from the already-printed Q1FY27 run-rate — the bear is a reversion case, not a 'flat' case. [AR FY26 MD&A p58/pr47; Q1FY27 IP slide 13]
A9: Premium ADT growth — FY28E (%) | E9: 0.08 | F9: -0.05 | G9: 0.35 | H9: =CHOOSE($C$4,E9,F9,G9) | I9: Bull = the 34.97%/yr for 3 years the research says the price requires.
A10: Premium ADT growth — FY29E (%) | E10: 0.0646 | F10: 0 | G10: 0.35 | H10: =CHOOSE($C$4,E10,F10,G10) | I10: Base set EQUAL to two-exchange pool growth (6.46%) so implied market share STOPS rising — otherwise the base case silently assumes BSE keeps taking share from NSE forever, which contradicts 'share gains exhaust'. Check the implied FY29E share on the Checks tab.
A11: Derivatives realisation (Rs cr per Rs cr premium ADT) | C11: 0.157668 | D11: 0.160547 | E11: 0.15252 | F11: 0.144492 | G11: 0.160547 | H11: =CHOOSE($C$4,E11,F11,G11) | I11: FY26 = 3,134.37/19,523 = 0.160547 (+1.83% on FY25). Q1FY27 realisation went FLAT then -1.63%. Base holds it 5% below FY26 per the research's base case.
A12: DRIVER 2 — the premium/notional WEDGE (the levy rides this)
A13: Premium / notional ratio (%) | C13: 0.00081126 | D13: 0.00104315 | E13: 0.00104315 | F13: 0.00091491 | G13: 0.00124959 | H13: =CHOOSE($C$4,E13,F13,G13) | I13: THE key variable. FY26 0.104315%. Bear = Q2FY26 low 0.091491% ALREADY PRINTED this cycle (costs Rs385cr of derivatives revenue). Bull = Q1FY27 high 0.124959%. Management: 'it is, of course, not predictable'.
A14: SEBI levy rate (Rs cr per Rs cr notional ADT) | C14: 2.995e-05 | D14: 3.025e-05 | E14: 3.025e-05 | F14: 3.025e-05 | G14: 3.025e-05 | H14: =CHOOSE($C$4,E14,F14,G14) | I14: FY26 566.16/18,715,375 = 0.00003025. Tracked its base to +1.0%. SEBI sets the rate; a rate change is a separate thesis-breaker, held flat here.
A15: DRIVER 3 — CONTRACT COUNT (clearing cost rides this)
A16: Contract count growth (%) | E16: 0.05 | F16: -0.1 | G16: 0.15 | H16: =CHOOSE($C$4,E16,F16,G16) | I16: FY26 contracts FELL 6.53% while revenue rose 63.46% — proof the three series diverge. Avg daily lots 153mn (Q2FY25) -> 100mn (Q2FY26).
A17: Clearing cost per contract-index unit (Rs cr) | D17: 280.35 | E17: 280.35 | F17: 300 | G17: 260 | H17: =CHOOSE($C$4,E17,F17,G17) | I17: FY26 clearing 280.35cr at contracts index 1.000. Fell 19.45% while notional rose 69.11% (81.18% of the fall was an intra-group elimination, per W3_cost).
A18: EQUITY CASH SEGMENT
A19: Cash ADT growth (%) | E19: 0.02 | F19: -0.1 | G19: 0.06 | H19: =CHOOSE($C$4,E19,F19,G19) | I19: FY26 cash ADT Rs7,950cr (+2.36%). Three down-years in ten; FY18->FY20 peak-to-trough -39.2%.
A20: Cash realisation (Rs cr per Rs cr cash ADT) | C20: 0.039088 | D20: 0.031473 | E20: 0.0288 | F20: 0.0271 | G20: 0.031473 | H20: =CHOOSE($C$4,E20,F20,G20) | I20: FY26 = 250.21/7,950 = 0.031473, DOWN 19.48% on a RISING volume base (a repricing, not a volume effect). Q1FY27 a further -13.93%.
A21: OTHER REVENUE LINES (growth on prior year)
A22: StAR MF platform fees growth (%) | E22: 0.15 | F22: 0 | G22: 0.25 | H22: =CHOOSE($C$4,E22,F22,G22) | I22: FY26 +23%. But realisation per order FELL 2.56%, then 6.33% in Q1FY27.
A23: Listing fees growth (%) | E23: 0.1 | F23: 0.04 | G23: 0.14 | H23: =CHOOSE($C$4,E23,F23,G23) | I23: FY26 +10%. Annual fee per listed company Rs4.273 lakh, +4.01% — the ONLY rising realisation.
A24: Book building / IPO fees growth (%) | E24: 0.1 | F24: -0.1 | G24: 0.2 | H24: =CHOOSE($C$4,E24,F24,G24) | I24: FY26 +9%. Cyclical with the IPO pipeline.
A25: Data feed & index licensing growth (%) | E25: 0.14 | F25: 0.05 | G25: 0.22 | H25: =CHOOSE($C$4,E25,F25,G25) | I25: Colocation +133% in FY26 off a small base; Asia Index/S&P BSE licensing.
A26: Other operating income growth (%) | E26: 0.1 | F26: 0 | G26: 0.15 | H26: =CHOOSE($C$4,E26,F26,G26) | I26: Residual other operating income.
A27: Currency derivatives txn charges (Rs cr) | D27: 0 | E27: 0 | F27: 0 | G27: 0 | H27: =CHOOSE($C$4,E27,F27,G27) | I27: EXTINGUISHED. RBI's 5-Jan-2024 directions took currency-derivatives ADT from Rs9,734cr to NIL. Two of five derivative segments extinguished in four years. Kept as an explicit line at zero.
A28: SLB (securities lending) txn charges (Rs cr) | D28: 0 | E28: 0 | F28: 0 | G28: 0 | H28: =CHOOSE($C$4,E28,F28,G28) | I28: NOT-DISCLOSED separately -> AR audited Note 22. Immaterial; explicit zero.
A29: Other regulatory & sundry expense (Rs cr) | D29: 77.97 | E29: 77.97 | F29: 85 | G29: 70 | H29: =CHOOSE($C$4,E29,F29,G29) | I29: RECONCILIATION LINE. Bridges the component build to reported total expenses of Rs1,837.42cr. Exists because the MD&A 'regulatory contribution' caption (Rs649.69cr) and the audited expense lines group the SEBI fee and Core SGF differently. Ties FY26 exactly; held flat forward.
A30: PAT attributable / PAT total (x) | D30: 1.0039 | E30: 1.0039 | F30: 1.0039 | G30: 1.0039 | H30: =CHOOSE($C$4,E30,F30,G30) | I30: FY26 2,496.98/2,487.25 = 1.0039 — non-controlling interests are marginally loss-making.
A31: Profit from discontinued operations (Rs cr) | D31: 11.95 | E31: 0 | F31: 0 | G31: 0 | H31: =CHOOSE($C$4,E31,F31,G31) | I31: FY26 Rs11.95cr (Rs1,195 lakh). Explains the PBT-less-tax vs reported-PAT gap exactly. Nil projected — it is by definition non-recurring.
A32: Audited-vs-MD&A transaction revenue uplift (x) | D32: 1.0342 | E32: 1.0342 | F32: 1.0342 | G32: 1.0342 | H32: =CHOOSE($C$4,E32,F32,G32) | I32: The audited transaction-charges line is Rs3,794.99cr against the MD&A build of Rs3,669.48cr (3,794.99/3,669.48 = 1.0342). The Core SGF policy rate applies to the AUDITED base, so the build is grossed up. This gap exists because the product split is unaudited.
A33: TREASURY — own corpus vs earmarked float (kept separate)
A34: Own investible corpus growth (%) | E34: 0.15 | F34: 0.05 | G34: 0.2 | H34: =CHOOSE($C$4,E34,F34,G34) | I34: Own corpus closing FY26 Rs6,101.90cr (+66.3%). This is SHAREHOLDERS' money.
A35: Own-corpus yield (%) | C35: 0.075 | D35: 0.05942 | E35: 0.05942 | F35: 0.05 | G35: 0.065 | H35: =CHOOSE($C$4,E35,F35,G35) | I35: Yield FELL 7.500% -> 5.942%, -156bp/-20.8%. Held at the FY26 realised level in base.
A36: Earmarked clearing float growth (%) | E36: 0.05 | F36: -0.1 | G36: 0.1 | H36: =CHOOSE($C$4,E36,F36,G36) | I36: Clearing/settlement float Rs3,554cr FY26. NOT owner cash — excluded from equity value.
A37: Float yield (%) | C37: 0.0632 | D37: 0.0499 | E37: 0.0499 | F37: 0.04 | G37: 0.06 | H37: =CHOOSE($C$4,E37,F37,G37) | I37: Treasury on clearing float 6.32% -> 4.99%, -21.0%.
A38: OPERATING COSTS
A39: Employee cost growth (%) | E39: 0.12 | F39: 0.1 | G39: 0.14 | H39: =CHOOSE($C$4,E39,F39,G39) | I39: FY26 +26% (incl Rs13.01cr non-recurring gratuity past-service cost).
A40: Technology cost growth (%) | E40: 0.15 | F40: 0.12 | G40: 0.18 | H40: =CHOOSE($C$4,E40,F40,G40) | I40: FY26 +24%. Data-centre and platform build.
A41: Other admin cost growth (%) | E41: 0.09 | F41: 0.08 | G41: 0.1 | H41: =CHOOSE($C$4,E41,F41,G41) | I41: Other administrative expenses.
...

Sheet Drivers & History
A1: BSE Ltd — Driver Series (the three exogenous variables)
A2: Management: 'the SEBI turnover fee is based on the notional trading, the clearing expense is based on the number of contracts, and we earn revenue based on premium'. Those are three different series and they diverge — FY26 revenue +63.46%, notional +69.12%, contracts -6.53%.
A3: ADT figures in Rs crore. Historical actuals in blue. Projections reference Assumptions ACTIVE column.
B4: Actual | E4: Projected
A5: Rs Crore / as marked | B5: FY24 | C5: FY25 | D5: FY26 | E5: FY27E | F5: FY28E | G5: FY29E | H5: Source / formula basis
A6: DRIVER 1 — index-options PREMIUM ADT (revenue base)
A7: Premium ADT (Rs cr) | C7: 8978 | D7: 19523 | E7: =D7*(1+Assumptions!$H$8) | F7: =E7*(1+Assumptions!$H$9) | G7: =F7*(1+Assumptions!$H$10) | H7: FY24 NOT DISCLOSED at this granularity. FY27E-FY29E = prior x (1 + growth) per year.
A8: DRIVER 2 — the WEDGE and the NOTIONAL base it implies
A9: Premium / notional ratio | C9: 0.00081126 | D9: 0.00104315 | E9: =Assumptions!$H$13 | F9: =Assumptions!$H$13 | G9: =Assumptions!$H$13 | H9: THE key variable. Quarterly range 0.091491% - 0.124959% = +/-37% inside eight quarters.
A10: Notional ADT (Rs cr) = premium / wedge | C10: =C7/C9 | D10: =D7/D9 | E10: =E7/E9 | F10: =F7/F9 | G10: =G7/G9 | H10: DERIVED. FY26 19,523/0.104315% = 18,715,429 (actual 18,715,375). 958.6x the base BSE bills on.
A11: DRIVER 3 — CONTRACT COUNT (clearing-cost base), indexed FY26 = 1.000
A12: Contract count index | C12: 1.0699 | D12: 1 | E12: =D12*(1+Assumptions!$H$16) | F12: =E12*(1+Assumptions!$H$16) | G12: =F12*(1+Assumptions!$H$16) | H12: Only the CHANGE is disclosed (-6.53% in FY26), not an audited annual count. FY25 index = 1/(1-0.0653) = 1.0699.
A13: EQUITY CASH — average daily turnover
A14: Cash ADT (Rs cr) | B14: 6622 | C14: 7766 | D14: 7950 | E14: =D14*(1+Assumptions!$H$19) | F14: =E14*(1+Assumptions!$H$19) | G14: =F14*(1+Assumptions!$H$19) | H14: Eleven-year series on the Drivers reference block below. Three down-years in ten.
A15: TREASURY — own corpus (shareholders') vs earmarked float (members')
A16: Own investible corpus — closing (Rs cr) | C16: 3669.77 | D16: 6101.9 | E16: =D16*(1+Assumptions!$H$34) | F16: =E16*(1+Assumptions!$H$34) | G16: =F16*(1+Assumptions!$H$34) | H16: SHAREHOLDERS' money. Closing FY26 Rs6,101.90cr (+66.3%).
A17: Own corpus — average (Rs cr) | C17: 3395.97 | D17: 4885.84 | E17: =AVERAGE(D16,E16) | F17: =AVERAGE(E16,F16) | G17: =AVERAGE(F16,G16) | H17: Average of opening and closing. Drives investment income.
A18: Earmarked clearing/settlement float (Rs cr) | B18: 3581.65 | C18: 3311.72 | D18: 3554.23 | E18: =D18*(1+Assumptions!$H$36) | F18: =E18*(1+Assumptions!$H$36) | G18: =F18*(1+Assumptions!$H$36) | H18: MEMBERS' money, not shareholders'. Excluded from equity value. Its movement is what inflates reported CFO.
A20: REFERENCE — eleven-year equity cash ADT (Rs cr) | B20: FY16 | C20: FY17 | D20: FY18 | E20: FY19 | F20: FY20 | G20: FY21 | H20: FY22 | I20: FY23 | J20: FY24 | K20: FY25 | L20: FY26
A21: FY16 - FY26 | B21: 2996 | C21: 4025 | D21: 4402 | E21: 3127 | F21: 2676 | G21: 4197 | H21: 5396 | I21: 4132 | J21: 6622 | K21: 7766 | L21: 7950 | M21: Three down-years in ten; FY18->FY20 peak-to-trough -39.2%.
A23: REFERENCE — the wedge, quarterly (the band that matters) | B23: Q1FY26 | C23: Q2FY26 | D23: Q3FY26 | E23: Q4FY26 | F23: Q1FY27
A24: Q1FY26 - Q1FY27 | B24: 0.00115144 | C24: 0.00091491 | D24: 0.00092662 | E24: 0.00118044 | F24: 0.00124959 | H24: Q2FY26 is the low ALREADY PRINTED -> the bear case.
A26: REFERENCE — Q1FY27 actuals (the reality check) | B26: Q1FY27 | C26: x4 annualised
A27: Q1FY27 revenue ops | B27: 1566.02 | C27: =B27*4 | H27: Revenue grew +0.16% SEQUENTIALLY; 110.1% of the profit increase was non-operating.
A28: Q1FY27 investment income | B28: 135.18 | C28: =B28*4
A29: Q1FY27 other income | B29: 5.52 | C29: =B29*4
A30: Q1FY27 total income | B30: 1706.72 | C30: =B30*4
A31: Q1FY27 employee | B31: 87.05 | C31: =B31*4
A32: Q1FY27 technology | B32: 60.82 | C32: =B32*4
A33: Q1FY27 clearing | B33: 90.28 | C33: =B33*4
A34: Q1FY27 regulatory | B34: 192.78 | C34: =B34*4
A35: Q1FY27 other expenses | B35: 63.16 | C35: =B35*4
A36: Q1FY27 depreciation | B36: 42.6 | C36: =B36*4
A37: Q1FY27 total expenses | B37: 536.69 | C37: =B37*4
A38: Q1FY27 pbt | B38: 1163.66 | C38: =B38*4

Sheet Income Statement
A1: BSE Ltd — Consolidated Income Statement
A2: SEBI levy computed on NOTIONAL turnover; clearing on CONTRACT COUNT; Core SGF at announced POLICY. An ex-levy COST FLOOR prevents controllable opex falling with revenue — the research records that the floor 'has never contracted in a down year'.
A3: Units: Rs Crore, consolidated. Historical actuals blue; projections formula-driven.
B4: Actual | E4: Projected
A5: Rs Crore / as marked | B5: FY24 | C5: FY25 | D5: FY26 | E5: FY27E | F5: FY28E | G5: FY29E | H5: Source / formula basis
A6: INCOME
A7: Revenue from operations | B7: ='Segment Revenue Build'!B21 | C7: ='Segment Revenue Build'!C21 | D7: ='Segment Revenue Build'!D21 | E7: ='Segment Revenue Build'!E21 | F7: ='Segment Revenue Build'!F21 | G7: ='Segment Revenue Build'!G21 | H7: Link to Segment Revenue Build.
A8: Investment income (own treasury) | B8: ='Segment Revenue Build'!B23 | C8: ='Segment Revenue Build'!C23 | D8: ='Segment Revenue Build'!D23 | E8: ='Segment Revenue Build'!E23 | F8: ='Segment Revenue Build'!F23 | G8: ='Segment Revenue Build'!G23 | H8: Link to Segment tab. NOT part of operating FCFF.
A9: Other income | B9: 25.4 | C9: 24.27 | D9: 23.85 | E9: =Assumptions!$H$48 | F9: =Assumptions!$H$48 | G9: =Assumptions!$H$48 | H9: From Assumptions.
A10: Total income | B10: =B7+B8+B9 | C10: =C7+C8+C9 | D10: =D7+D8+D9 | E10: =E7+E8+E9 | F10: =F7+F8+F9 | G10: =G7+G8+G9
A11: CONTROLLABLE OPERATING EXPENSES
A12: Employee benefits expense | B12: 204.71 | C12: 236.62 | D12: 297.81 | E12: =D12*(1+Assumptions!$H$39) | F12: =E12*(1+Assumptions!$H$39) | G12: =F12*(1+Assumptions!$H$39) | H12: Prior x (1 + growth).
A13: Technology & operating expense | B13: 137.44 | C13: 164.29 | D13: 203.13 | E13: =D13*(1+Assumptions!$H$40) | F13: =E13*(1+Assumptions!$H$40) | G13: =F13*(1+Assumptions!$H$40) | H13: Prior x (1 + growth).
A14: Clearing & settlement expense | B14: 133.14 | C14: 348.05 | D14: 280.35 | E14: ='Drivers & History'!E12*Assumptions!$H$17 | F14: ='Drivers & History'!F12*Assumptions!$H$17 | G14: ='Drivers & History'!G12*Assumptions!$H$17 | H14: = CONTRACT INDEX x cost per unit. FY26 fell 19.45% while notional rose 69.11% — proof the driver is contracts, not turnover. (v1 wrongly used % of revenue.)
A15: Other administrative expenses | B15: 338.84 | C15: 201.54 | D15: 247.32 | E15: =D15*(1+Assumptions!$H$41) | F15: =E15*(1+Assumptions!$H$41) | G15: =F15*(1+Assumptions!$H$41) | H15: Prior x (1 + growth).
A16: Depreciation & amortisation | B16: 95.44 | C16: 112.98 | D16: 158.96 | E16: ='Balance Sheet'!E9 | F16: ='Balance Sheet'!F9 | G16: ='Balance Sheet'!G9 | H16: Links to the Balance Sheet capex/D&A schedule.
A17: Controllable opex — computed | B17: =B12+B13+B14+B15+B16 | C17: =C12+C13+C14+C15+C16 | D17: =D12+D13+D14+D15+D16 | E17: =E12+E13+E14+E15+E16 | F17: =F12+F13+F14+F15+F16 | G17: =G12+G13+G14+G15+G16 | H17: Sum of the controllable lines above.
A18: Ex-levy cost FLOOR (inflated) | D18: 1187.73 | E18: =$D$18*(1+Assumptions!$H$43)^1 | F18: =$D$18*(1+Assumptions!$H$43)^2 | G18: =$D$18*(1+Assumptions!$H$43)^3 | H18: FY26 ex-levy run rate Rs1,187.73cr. 'That floor has never contracted in a down year.' [W7_bearcase]
A19: Controllable opex — APPLIED (floor enforced) | B19: =B17 | C19: =C17 | D19: =D17 | E19: =IF(Assumptions!$H$42=1,MAX(E17,E18),E17) | F19: =IF(Assumptions!$H$42=1,MAX(F17,F18),F17) | G19: =IF(Assumptions!$H$42=1,MAX(G17,G18),G17) | H19: MAX(computed, floor) when the switch is ON.
A20: of which: floor uplift (binding when > 0) | B20: =B19-B17 | C20: =C19-C17 | D20: =D19-D17 | E20: =E19-E17 | F20: =F19-F17 | G20: =G19-G17 | H20: Shows how much cost the floor is holding in place.
A21: REGULATORY COSTS (set by SEBI, not by BSE)
A22: SEBI regulatory fee (on NOTIONAL turnover) | B22: 169.77 | C22: 331.41 | D22: 566.16 | E22: ='Drivers & History'!E10*Assumptions!$H$14 | F22: ='Drivers & History'!F10*Assumptions!$H$14 | G22: ='Drivers & History'!G10*Assumptions!$H$14 | H22: = NOTIONAL ADT x levy rate. 11.71% of BSE revenue vs NSE's 4.80% = 2.44x, because BSE bills on premium and pays on notional (958.6x the base).
A23: Core SGF contribution | B23: 91.7 | C23: 90 | D23: 76.96 | E23: =IF(Assumptions!$H$44=2,'Segment Revenue Build'!E12*Assumptions!$H$32*Assumptions!$H$45,D23*(1+Assumptions!$H$41)) | F23: =IF(Assumptions!$H$44=2,'Segment Revenue Build'!F12*Assumptions!$H$32*Assumptions!$H$45,E23*(1+Assumptions!$H$41)) | G23: =IF(Assumptions!$H$44=2,'Segment Revenue Build'!G12*Assumptions!$H$32*Assumptions!$H$45,F23*(1+Assumptions!$H$41)) | H23: Mode 2 = announced policy 5% of transaction revenue (Rs189.75cr) vs Rs76.96cr charged = 2.47x. Permanent cash into a RESTRICTED fund. Counter-cyclical.
A24: Other regulatory & sundry expense | D24: 77.97 | E24: =Assumptions!$H$29 | F24: =Assumptions!$H$29 | G24: =Assumptions!$H$29 | H24: Reconciliation line — bridges the component build to reported total expenses.
A25: TOTAL EXPENSES | B25: 1100.82 | C25: 1480.63 | D25: 1837.42 | E25: =E19+E22+E24 | F25: =F19+F22+F24 | G25: =G19+G22+G24 | H25: Projected = controllable applied + SEBI levy + other reg. Core SGF is deducted separately below, matching the reported PBT identity.
A26: PROFIT
A27: EBITDA (incl investment income) | B27: =B10-B25+B16 | C27: =C10-C25+C16 | D27: =D10-D25+D16 | E27: =E10-E25+E16 | F27: =F10-F25+F16 | G27: =G10-G25+G16
A28: Memo: float income inside revenue (members' money) | B28: ='Drivers & History'!B18*Assumptions!$H$37 | C28: ='Drivers & History'!C18*Assumptions!$H$37 | D28: ='Drivers & History'!D18*Assumptions!$H$37 | E28: ='Drivers & History'!E18*Assumptions!$H$37 | F28: ='Drivers & History'!F18*Assumptions!$H$37 | G28: ='Drivers & History'!G18*Assumptions!$H$37 | H28: Rs171.42cr in FY26: interest earned on MEMBERS' clearing float at 4.99%, credited to shareholders as revenue. Not customer income.
A29: OPERATING EBIT (excl investment & other income) | B29: =B7-B25-B23-IF(Assumptions!$H$74=1,B28,0) | C29: =C7-C25-C23-IF(Assumptions!$H$74=1,C28,0) | D29: =D7-D25-D23-IF(Assumptions!$H$74=1,D28,0) | E29: =E7-E25-E23-IF(Assumptions!$H$74=1,E28,0) | F29: =F7-F25-F23-IF(Assumptions!$H$74=1,F28,0) | G29: =G7-G25-G23-IF(Assumptions!$H$74=1,G28,0) | H29: THE DCF BASE. Revenue less all operating cost incl SGF, less float income when the strip switch is on. Excludes treasury income so the corpus is not capitalised twice.
A30: Finance cost | B30: 15.05 | C30: 0.03 | D30: 0.16 | E30: =Assumptions!$H$49 | F30: =Assumptions!$H$49 | G30: =Assumptions!$H$49 | H30: Effectively debt-free.
A31: Share of associate profit (CDSL) | B31: 71.82 | C31: 82.59 | D31: 65.42 | E31: =IF(Assumptions!$H$69=1,Assumptions!$H$47,0) | F31: =IF(Assumptions!$H$69=1,Assumptions!$H$47,0) | G31: =IF(Assumptions!$H$69=1,Assumptions!$H$47,0) | H31: Mode 1 = keep the equity earnings here and value the stake at nil. Mode 2 = strip these earnings and add the stake's MARKET value in the DCF bridge instead. Never both.
A32: Exceptional items | B32: 406.62 | C32: 0 | D32: 0 | E32: =Assumptions!$H$50 | F32: =Assumptions!$H$50 | G32: =Assumptions!$H$50 | H32: Nil projected.
A33: Profit before tax | B33: 995.52 | C33: 1748.27 | D33: 3299.14 | E33: =E29+IF(Assumptions!$H$74=1,E28,0)+E8+E9-E30+E31+E32 | F33: =F29+IF(Assumptions!$H$74=1,F28,0)+F8+F9-F30+F31+F32 | G33: =G29+IF(Assumptions!$H$74=1,G28,0)+G8+G9-G30+G31+G32 | H33: Float income is added back here because it IS in reported revenue and reported PBT — it is removed only from the FCFF base.
A34: Tax expense | B34: 223.86 | C34: 431.21 | D34: 823.84 | E34: =E33*Assumptions!$H$55 | F34: =F33*Assumptions!$H$55 | G34: =G33*Assumptions!$H$55 | H34: PBT x effective tax rate.
A35: Profit from discontinued operations | C35: 5.26 | D35: 11.95 | E35: =Assumptions!$H$31 | F35: =Assumptions!$H$31 | G35: =Assumptions!$H$31 | H35: FY26 Rs11.95cr — explains the PBT-less-tax vs reported-PAT gap exactly. Nil projected.
A36: Profit after tax (total) | B36: =B33-B34+B35 | C36: =C33-C34+C35 | D36: =D33-D34+D35 | E36: =E33-E34+E35 | F36: =F33-F34+F35 | G36: =G33-G34+G35
A37: PAT attributable to owners | B37: =B36*Assumptions!$H$30 | C37: =C36*Assumptions!$H$30 | D37: =D36*Assumptions!$H$30 | E37: =E36*Assumptions!$H$30 | F37: =F36*Assumptions!$H$30 | G37: =G36*Assumptions!$H$30 | H37: PAT total x attribution factor. This is the EPS numerator.
A38: EPS (Rs) — on ISSUED shares | B38: =B37/Assumptions!$H$72 | C38: =C37/Assumptions!$H$72 | D38: =D37/Assumptions!$H$72 | E38: =E37/Assumptions!$H$72 | F38: =F37/Assumptions!$H$72 | G38: =G37/Assumptions!$H$72 | H38: Audited basis: 2,496.98/41.1979 = Rs60.61 for FY26. Dividing by PAID-UP shares would print Rs61.22 — that is the wrong denominator for EPS.
A39: Memo: MTM revaluation inside investment income | B39: =B8*(1-Assumptions!$H$73) | C39: =C8*(1-Assumptions!$H$73) | D39: =D8*(1-Assumptions!$H$73) | E39: =E8*(1-Assumptions!$H$73) | F39: =F8*(1-Assumptions!$H$73) | G39: =G8*(1-Assumptions!$H$73) | H39: ~30.57% of investment income is mark-to-market revaluation — 'not a yield and should not carry an operating multiple' [W5].
A40: Quality-adjusted EPS (Rs) — MTM removed | B40: =(B37-B39*(1-Assumptions!$H$55))/Assumptions!$H$72 | C40: =(C37-C39*(1-Assumptions!$H$55))/Assumptions!$H$72 | D40: =(D37-D39*(1-Assumptions!$H$55))/Assumptions!$H$72 | E40: =(E37-E39*(1-Assumptions!$H$55))/Assumptions!$H$72 | F40: =(F37-F39*(1-Assumptions!$H$55))/Assumptions!$H$72 | G40: =(G37-G39*(1-Assumptions!$H$55))/Assumptions!$H$72 | H40: The earnings an operating multiple should be struck on.
...

Sheet Balance Sheet
A1: BSE Ltd — Consolidated Balance Sheet
A2: Own-account money is separated from EARMARKED clearing/settlement balances (members' money). Only own-account funds belong to shareholders and only they enter equity value.
A3: Units: Rs Crore. Balance check must be 0 in projected years.
B4: Actual | E4: Projected
A5: Rs Crore / as marked | B5: FY24 | C5: FY25 | D5: FY26 | E5: FY27E | F5: FY28E | G5: FY29E | H5: Source / formula basis
A6: CAPEX & DEPRECIATION SCHEDULE
A7: Net block — opening | E7: =D10 | F7: =E10 | G7: =F10
A8: Capex | B8: 131.32 | C8: 153.23 | D8: 515.16 | E8: ='Income Statement'!E7*Assumptions!$H$51 | F8: ='Income Statement'!F7*Assumptions!$H$51 | G8: ='Income Statement'!G7*Assumptions!$H$51 | H8: Projected = revenue x capex%. FY26 was elevated (data-centre).
A9: Depreciation & amortisation | B9: 95.44 | C9: 112.98 | D9: 158.96 | E9: =E7*Assumptions!$H$52 | F9: =F7*Assumptions!$H$52 | G9: =G7*Assumptions!$H$52
A10: Net block — closing (PPE + CWIP) | B10: 209.54 | C10: 262.9 | D10: 595.14 | E10: =E7+E8-E9 | F10: =F7+F8-F9 | G10: =G7+G8-G9
A11: ASSETS
A12: Own investible corpus (shareholders') | B12: 1415.28 | C12: ='Drivers & History'!C16 | D12: ='Drivers & History'!D16 | E12: ='Drivers & History'!E16 | F12: ='Drivers & History'!F16 | G12: ='Drivers & History'!G16 | H12: Link to Drivers. THIS is what enters equity value.
A13: Earmarked funds (members' — clearing/settlement) | B13: 4892.49 | C13: 4681.09 | D13: 5006.57 | E13: =D13*(1+Assumptions!$H$36) | F13: =E13*(1+Assumptions!$H$36) | G13: =F13*(1+Assumptions!$H$36) | H13: NOT shareholders' money. Matched by an equal liability.
A14: Trade receivables | B14: 210.87 | C14: 309.67 | D14: 553.16 | E14: ='Income Statement'!E7*Assumptions!$H$53/365 | F14: ='Income Statement'!F7*Assumptions!$H$53/365 | G14: ='Income Statement'!G7*Assumptions!$H$53/365
A15: Other assets (residual) | B15: 2722.05 | C15: 3413.13 | D15: 4205.31 | E15: =D15*(1+Assumptions!$H$34) | F15: =E15*(1+Assumptions!$H$34) | G15: =F15*(1+Assumptions!$H$34) | H15: Asset-side residual so historical total ties to the reported figure.
A16: TOTAL ASSETS | B16: =B10+B12+B13+B14+B15 | C16: =C10+C12+C13+C14+C15 | D16: =D10+D12+D13+D14+D15 | E16: =E10+E12+E13+E14+E15 | F16: =F10+F12+F13+F14+F15 | G16: =G10+G12+G13+G14+G15
A17: EQUITY & LIABILITIES
A18: Total equity | B18: 3454.66 | C18: 4575.7 | D18: 6795.5 | E18: =D18+'Income Statement'!E37-'Income Statement'!E41 | F18: =E18+'Income Statement'!F37-'Income Statement'!F41 | G18: =F18+'Income Statement'!G37-'Income Statement'!G41 | H18: Prior + PAT attributable - dividend.
A19: Earmarked liabilities (members' obligations) | B19: =B13 | C19: =C13 | D19: =D13 | E19: =E13 | F19: =F13 | G19: =G13 | H19: Set equal to earmarked assets — a pass-through, not leverage.
A20: Own payables & provisions | B20: 0 | C20: 0 | D20: 0 | E20: ='Income Statement'!E19*Assumptions!$H$54 | F20: ='Income Statement'!F19*Assumptions!$H$54 | G20: ='Income Statement'!G19*Assumptions!$H$54 | H20: Driven off the COST base, not revenue (v1 error B16).
A21: Other liabilities (residual / plug) | B21: 1103.08 | C21: 1084.86 | D21: 1644.07 | E21: =E16-E18-E19-E20 | F21: =F16-F18-F19-F20 | G21: =G16-G18-G19-G20 | H21: Balancing item so the sheet balances identically.
A22: TOTAL EQUITY & LIABILITIES | B22: =B18+B19+B20+B21 | C22: =C18+C19+C20+C21 | D22: =D18+D19+D20+D21 | E22: =E18+E19+E20+E21 | F22: =F18+F19+F20+F21 | G22: =G18+G19+G20+G21
A23: BALANCE CHECK (Assets - E&L) | B23: =B16-B22 | C23: =C16-C22 | D23: =D16-D22 | E23: =E16-E22 | F23: =F16-F22 | G23: =G16-G22

Sheet Cash Flow
A1: BSE Ltd — Cash Flow: headline vs OWN-ACCOUNT
A2: The report's central cash finding: conversion is 1.272 headline and 0.712 own-account — the printed number is 78.7% too high, because reported CFO absorbs movements in members' clearing float that are not shareholders' cash. This tab separates the two.
A3: Units: Rs Crore.
B4: Actual | E4: Projected
A5: Rs Crore / as marked | B5: FY24 | C5: FY25 | D5: FY26 | E5: FY27E | F5: FY28E | G5: FY29E | H5: Source / formula basis
A6: OPERATING CASH FLOW
A7: PAT attributable | B7: ='Income Statement'!B37 | C7: ='Income Statement'!C37 | D7: ='Income Statement'!D37 | E7: ='Income Statement'!E37 | F7: ='Income Statement'!F37 | G7: ='Income Statement'!G37
A8: add: D&A | B8: ='Income Statement'!B16 | C8: ='Income Statement'!C16 | D8: ='Income Statement'!D16 | E8: ='Income Statement'!E16 | F8: ='Income Statement'!F16 | G8: ='Income Statement'!G16
A9: less: increase in receivables | C9: =-('Balance Sheet'!C14-'Balance Sheet'!B14) | D9: =-('Balance Sheet'!D14-'Balance Sheet'!C14) | E9: =-('Balance Sheet'!E14-'Balance Sheet'!D14) | F9: =-('Balance Sheet'!F14-'Balance Sheet'!E14) | G9: =-('Balance Sheet'!G14-'Balance Sheet'!F14)
A10: add: increase in EARMARKED float (members' money) | C10: =('Balance Sheet'!C13-'Balance Sheet'!B13) | D10: =('Balance Sheet'!D13-'Balance Sheet'!C13) | E10: =('Balance Sheet'!E13-'Balance Sheet'!D13) | F10: =('Balance Sheet'!F13-'Balance Sheet'!E13) | G10: =('Balance Sheet'!G13-'Balance Sheet'!F13) | H10: THIS is the line that inflates headline CFO. It is not shareholders' cash.
A11: CFO — HEADLINE (as reported basis) | C11: =C7+C8+C9+C10 | D11: =D7+D8+D9+D10 | E11: =E7+E8+E9+E10 | F11: =F7+F8+F9+F10 | G11: =G7+G8+G9+G10
A12: CFO — OWN ACCOUNT (float movement removed) | C12: =C11-C10 | D12: =D11-D10 | E12: =E11-E10 | F12: =F11-F10 | G12: =G11-G10 | H12: The number an owner can spend.
A13: INVESTING & FREE CASH FLOW
A14: less: capex | B14: =-'Balance Sheet'!B8 | C14: =-'Balance Sheet'!C8 | D14: =-'Balance Sheet'!D8 | E14: =-'Balance Sheet'!E8 | F14: =-'Balance Sheet'!F8 | G14: =-'Balance Sheet'!G8
A15: OWN-ACCOUNT FREE CASH FLOW | C15: =C12+C14 | D15: =D12+D14 | E15: =E12+E14 | F15: =F12+F14 | G15: =G12+G14
A16: less: dividend | B16: =-'Income Statement'!B41 | C16: =-'Income Statement'!C41 | D16: =-'Income Statement'!D41 | E16: =-'Income Statement'!E41 | F16: =-'Income Statement'!F41 | G16: =-'Income Statement'!G41
A17: CONVERSION TESTS
A18: Headline CFO / PAT | C18: =C11/C7 | D18: =D11/D7 | E18: =E11/E7 | F18: =F11/F7 | G18: =G11/G7 | H18: Ten-year cumulative reported basis = 1.272.
A19: Own-account CFO / PAT | C19: =C12/C7 | D19: =D12/D7 | E19: =E12/E7 | F19: =F12/F7 | G19: =G12/G7 | H19: Ten-year cumulative own-account basis = 0.712. 1.272/0.712 = 1.787 -> the printed figure is 78.7% too high.

Sheet Segment Revenue Build
A1: BSE Ltd — Segment Revenue Build
A2: Derivatives = premium ADT x realisation. Cash = cash ADT x realisation. WARNING: the product split is UNAUDITED — it exists only in the MD&A. The audited Note 22 stops at one aggregate (78.51% of revenue in a single line). NOT-DISCLOSED -> Ind AS 115.114 disaggregation note.
A3: Units: Rs Crore. Historical = STANDALONE MD&A split; consolidated via an explicit scalar.
B4: Actual | E4: Projected
A5: Rs Crore / as marked | B5: FY24 | C5: FY25 | D5: FY26 | E5: FY27E | F5: FY28E | G5: FY29E | H5: Source / formula basis
A6: TRANSACTION CHARGES
A7: Equity derivatives txn charges | C7: 1415.54 | D7: 3134.37 | E7: ='Drivers & History'!E7*Assumptions!$H$11 | F7: ='Drivers & History'!F7*Assumptions!$H$11 | G7: ='Drivers & History'!G7*Assumptions!$H$11 | H7: = premium ADT x realisation. 64.84% of consolidated revenue — one product, one index, one regulator-allocated weekly expiry slot.
A8: Equity cash txn charges | C8: 303.56 | D8: 250.21 | E8: ='Drivers & History'!E14*Assumptions!$H$20 | F8: ='Drivers & History'!F14*Assumptions!$H$20 | G8: ='Drivers & History'!G14*Assumptions!$H$20 | H8: = cash ADT x realisation. FY26 fell 18% on RISING volume — a repricing.
A9: Currency derivatives txn charges | B9: 0 | C9: 0 | D9: 0 | E9: =Assumptions!$H$27 | F9: =Assumptions!$H$27 | G9: =Assumptions!$H$27 | H9: EXTINGUISHED by RBI direction (Rs9,734cr ADT -> nil).
A10: SLB txn charges | B10: 0 | C10: 0 | D10: 0 | E10: =Assumptions!$H$28 | F10: =Assumptions!$H$28 | G10: =Assumptions!$H$28 | H10: NOT-DISCLOSED separately; immaterial.
A11: StAR MF platform fees | C11: 230.77 | D11: 284.9 | E11: =D11*(1+Assumptions!$H$22) | F11: =E11*(1+Assumptions!$H$22) | G11: =F11*(1+Assumptions!$H$22) | H11: MF distribution platform. Realisation per order is FALLING (-2.56%, then -6.33%).
A12: Transaction charges — total | B12: =B7+B8+B9+B10+B11 | C12: =C7+C8+C9+C10+C11 | D12: =D7+D8+D9+D10+D11 | E12: =E7+E8+E9+E10+E11 | F12: =F7+F8+F9+F10+F11 | G12: =G7+G8+G9+G10+G11 | H12: Sum of components. Drives the Core SGF policy charge.
A13: NON-TRANSACTION REVENUE
A14: Listing fees (annual + processing) | C14: 353.28 | D14: 388.61 | E14: =D14*(1+Assumptions!$H$23) | F14: =E14*(1+Assumptions!$H$23) | G14: =F14*(1+Assumptions!$H$23) | H14: The ONLY line whose realisation rose (+4.01% per listed company).
A15: Book building / IPO fees | C15: 95.36 | D15: 104.12 | E15: =D15*(1+Assumptions!$H$24) | F15: =E15*(1+Assumptions!$H$24) | G15: =F15*(1+Assumptions!$H$24) | H15: Cyclical with the IPO pipeline.
A16: Data feed & index licensing income | C16: 72.62 | D16: 168.99 | E16: =D16*(1+Assumptions!$H$25) | F16: =E16*(1+Assumptions!$H$25) | G16: =F16*(1+Assumptions!$H$25) | H16: Colocation + Asia Index/S&P BSE licensing. FY26 colocation +133% off a small base.
A17: Other operating income (residual) | C17: 95.44 | D17: 112.11 | E17: =D17*(1+Assumptions!$H$26) | F17: =E17*(1+Assumptions!$H$26) | G17: =F17*(1+Assumptions!$H$26) | H17: Other operating income less colocation.
A18: REVENUE FROM OPERATIONS
A19: Revenue from operations — standalone build | B19: =B12+B14+B15+B16+B17 | C19: =C12+C14+C15+C16+C17 | D19: =D12+D14+D15+D16+D17 | E19: =E12+E14+E15+E16+E17 | F19: =F12+F14+F15+F16+F17 | G19: =G12+G14+G15+G16+G17
A20: Consolidation scalar (consol / standalone) | C20: =2957.34/C19 | D20: =4833.95/D19 | E20: =$D$20 | F20: =$D$20 | G20: =$D$20 | H20: FY26 1.0815 held flat (documented anchor). Subsidiaries ICCL/India INX/BSE Institute/BSE Technologies supply 7.5% of consolidated revenue.
A21: REVENUE FROM OPERATIONS — consolidated | B21: 1390.03 | C21: =C19*C20 | D21: =D19*D20 | E21: =E19*E20 | F21: =F19*F20 | G21: =G19*G20 | H21: FY24 = direct actual (no split disclosed). Feeds the Income Statement.
A22: INVESTMENT / TREASURY INCOME (own account only)
A23: Investment income (own corpus) | B23: 202.47 | C23: 254.7 | D23: 290.3 | E23: ='Drivers & History'!E17*Assumptions!$H$35 | F23: ='Drivers & History'!F17*Assumptions!$H$35 | G23: ='Drivers & History'!G17*Assumptions!$H$35 | H23: = average own corpus x own yield. FY26 4,885.84 x 5.942% = 290.30 (actual 290.30). EXCLUDED from FCFF — the corpus is added once in the DCF bridge instead.

Sheet DCF Valuation
A1: BSE Ltd — DCF Valuation (FCFF on OPERATIONS ONLY)
A2: FCFF is built from OPERATING EBIT, which excludes investment income. The treasury corpus is then added ONCE in the bridge. v1 capitalised the treasury twice (income stream + principal) — that double-count is removed here.
A3: Units: Rs Crore; per-share in Rs. BSE earns fee income (not a bank) so FCFF DCF applies.
A5: WACC BUILD-UP (CAPM)
A6: Risk-free rate | E6: =Assumptions!$H$58 | H6: From Assumptions (scenario-resolved).
A7: Equity risk premium | E7: =Assumptions!$H$59 | H7: From Assumptions.
A8: Beta (levered) | E8: =Assumptions!$H$60 | H8: Bear raises beta: one product, one expiry slot.
A9: Cost of equity (CAPM) | E9: =E6+E8*E7 | H9: Rf + beta x ERP.
A10: Pre-tax cost of debt | E10: =Assumptions!$H$61 | H10: From Assumptions.
A11: Tax rate | E11: =Assumptions!$H$55 | H11: From Assumptions.
A12: After-tax cost of debt | E12: =E10*(1-E11) | H12: Kd x (1 - t).
A13: Weight — equity | E13: =Assumptions!$H$62 | H13: From Assumptions.
A14: Weight — debt | E14: =1-E13 | H14: 1 - equity weight.
A15: WACC | E15: =E13*E9+E14*E12 | H15: We x Ke + Wd x Kd(AT).
A16: Terminal growth | E16: =Assumptions!$H$63 | H16: Base 4.0% — lowered from v1's 5% because FY26 is peak-cycle and ~9/10 of FY26 growth was share TRANSFER from NSE, which cannot compound forever.
A17: FREE CASH FLOW TO FIRM (operations only) | B17: Actual | E17: Projected
A18: Rs Crore / as marked | B18: FY24 | C18: FY25 | D18: FY26 | E18: FY27E | F18: FY28E | G18: FY29E | H18: Source / formula basis
A19: Operating EBIT (excl investment income) | E19: ='Income Statement'!E29 | F19: ='Income Statement'!F29 | G19: ='Income Statement'!G29 | H19: Link to IS operating EBIT. Treasury income deliberately EXCLUDED.
A20: NOPAT | E20: =E19*(1-Assumptions!$H$55) | F20: =F19*(1-Assumptions!$H$55) | G20: =G19*(1-Assumptions!$H$55) | H20: EBIT x (1 - tax).
A21: add: D&A | E21: ='Balance Sheet'!E9 | F21: ='Balance Sheet'!F9 | G21: ='Balance Sheet'!G9 | H21: Link to BS schedule.
A22: less: capex | E22: =-'Balance Sheet'!E8 | F22: =-'Balance Sheet'!F8 | G22: =-'Balance Sheet'!G8 | H22: Link to BS schedule.
A23: less: increase in operating WC | E23: =-('Balance Sheet'!E14-'Balance Sheet'!D14) | F23: =-('Balance Sheet'!F14-'Balance Sheet'!E14) | G23: =-('Balance Sheet'!G14-'Balance Sheet'!F14) | H23: Receivables only. Earmarked float is members' money and is NOT working capital.
A24: FCFF | E24: =E20+E21+E22+E23 | F24: =F20+F21+F22+F23 | G24: =G20+G21+G22+G23 | H24: NOPAT + D&A - capex - dWC.
A25: Discount period | E25: =1 | F25: =2 | G25: =3 | H25: 1, 2, 3.
A26: Discount factor | E26: =1/(1+$E$15)^E25 | F26: =1/(1+$E$15)^F25 | G26: =1/(1+$E$15)^G25 | H26: 1/(1+WACC)^n.
A27: PV of FCFF | E27: =E24*E26 | F27: =F24*F26 | G27: =G24*G26 | H27: FCFF x DF.
A28: TERMINAL VALUE AND THE BRIDGE TO EQUITY
A29: Terminal value — Gordon (single stage) | E29: =G24*(1+$E$16)/($E$15-$E$16) | H29: FCFF(final) x (1+g) / (WACC - g).
A30: Terminal value — H-model (two stage, fading) | E30: =G24*(1+$E$16)/($E$15-$E$16)+G24*(Assumptions!$H$66/2)*(Assumptions!$H$65-$E$16)/($E$15-$E$16) | H30: Gordon base + fade premium: FCFF x H x (g_fade - g) / (WACC - g), where H = fade_years/2. Credits the transition from high growth to maturity instead of assuming it ends instantly.
A31: Terminal value — APPLIED | E31: =IF(Assumptions!$H$64=1,E29,E30) | H31: Selected by the method switch on Assumptions.
A32: PV of terminal value | E32: =E31*G26 | H32: TV x final DF.
A33: Sum PV of explicit FCFF | E33: =SUM(E27:G27) | H33: Explicit period.
A34: Enterprise value — OPERATIONS | E34: =E33+E32 | H34: PV(FCFF) + PV(TV). Operations only.
A35: add: own investible corpus (once) | E35: ='Balance Sheet'!D12 | H35: FY26 own corpus Rs6,101.90cr — SHAREHOLDERS' money, added ONCE. Earmarked float is excluded because it belongs to members.
A36: add: CDSL stake market value | E36: =IF(Assumptions!$H$69=2,Assumptions!$H$68,0) | H36: Rs3,509.32cr [AR FY26, Note 8]. Included ONLY in mode 2, where the associate EARNINGS are simultaneously stripped from the P&L. Market value OR earnings, never both [W5 constraint 4].
A37: less: debt | E37: =0 | H37: BSE carries effectively no debt.
A38: EQUITY VALUE | E38: =E34+E35+E36-E37 | H38: Operations + treasury (once) + associate - debt.
A39: Shares outstanding (cr) | E39: =Assumptions!$H$71 | H39: From Assumptions.
A40: IMPLIED VALUE PER SHARE (Rs) | E40: =E38/E39 | H40: Equity value / shares. Both in crore units, so they cancel to Rs/share.
A41: Market price (Rs) | E41: =Assumptions!$H$70 | H41: NSE bhavcopy 4-Sep-2026.
...

Sheet Comps
A1: BSE Ltd — Trading Comparables
A2: HONESTY NOTE: no verified peer market data exists in this research corpus. Peer price / EBITDA / PAT / book cells are UNVERIFIED user inputs — refresh them before relying on any output. The one peer fact that IS evidenced (NSE's SEBI-fee burden) is shown separately as a real anchor.
A3: Units: Rs Crore; price in Rs; multiples in x.
A5: *** PEER MARKET DATA BELOW IS UNVERIFIED — USER MUST REFRESH ***
A7: Company | B7: Price (Rs) | C7: Shares (cr) | D7: Mkt cap | E7: Net debt | F7: EV | G7: PAT | H7: EBITDA
A8: MCX | B8: 6500 | C8: 5.1 | D8: =B8*C8 | E8: -900 | F8: =D8+E8 | G8: 560 | H8: 700
A9: CDSL | B9: 1500 | C9: 20.9 | D9: =B9*C9 | E9: -1200 | F9: =D9+E9 | G9: 620 | H9: 800
A10: BSE (from model) | B10: =Assumptions!$H$70 | C10: =Assumptions!$H$71 | D10: =B10*C10 | E10: =-'Balance Sheet'!D12 | F10: =D10+E10 | G10: ='Income Statement'!D37 | H10: ='Income Statement'!D27
A12: MULTIPLES
A13: Company | B13: EV/EBITDA | C13: P/E | D13: P/B
A14: MCX | B14: =F8/H8 | C14: =D8/G8 | D14: =NA()
A15: CDSL | B15: =F9/H9 | C15: =D9/G9 | D15: =NA()
A16: Peer average | B16: =AVERAGE(B14:B15) | C16: =AVERAGE(C14:C15)
A17: BSE (model) | B17: =F10/H10 | C17: =D10/G10 | D17: =D10/'Balance Sheet'!D18 | F17: BSE P/E should print ~55.7x — the report's figure at Rs3,409.80.
A19: IMPLIED VALUE FOR BSE FROM PEER MULTIPLES
A20: Implied price/share — EV/EBITDA (Rs) | B20: =(B16*H10-E10)/C10
A21: Implied price/share — P/E (Rs) | B21: =(C16*G10)/C10
A23: THE ONE EVIDENCED PEER FACT — the SEBI-fee burden
A24: NSE FY26 revenue from operations (Rs cr) | B24: 16601.31 | D24: [NSE AR FY26, Consolidated P&L, PDF p140/pr318]
A25: NSE FY26 SEBI regulatory fee (Rs cr) | B25: 796.35 | D25: same source
A26: NSE SEBI fee as % of revenue | B26: =B25/B24
A27: BSE SEBI fee as % of revenue | B27: ='Income Statement'!D22/'Income Statement'!D7
A28: BSE / NSE burden ratio | B28: =B27/B26 | D28: Research figure: 11.71% / 4.80% = 2.44x. BSE bills on premium, pays on notional.

Sheet Sensitivity
A1: BSE Ltd — Sensitivity
A2: Grid 1: WACC x terminal growth. Grid 2: premium-ADT growth. Grid 3: THE WEDGE — the premium/notional ratio, which the research identifies as the single most important exogenous variable and which management says is unforecastable.
A3: Value per share in Rs. Every grid cell is a live formula off the DCF FCFF stream.
A5: GRID 1 — value/share: WACC (across) x terminal growth (down)
A6: g \ WACC | B6: ='DCF Valuation'!$E$15-0.02 | C6: ='DCF Valuation'!$E$15-0.01 | D6: ='DCF Valuation'!$E$15+0.0 | E6: ='DCF Valuation'!$E$15+0.01 | F6: ='DCF Valuation'!$E$15+0.02
A7: ='DCF Valuation'!$E$16-0.02 | B7: =((1*'DCF Valuation'!$E$24/(1+B$6)^1+1*'DCF Valuation'!$F$24/(1+B$6)^2+1*'DCF Valuation'!$G$24/(1+B$6)^3+(1*'DCF Valuation'!$G$24*(1+$A7)/(B$6-$A7))/(1+B$6)^3)+'DCF Valuation'!$E$35)/'DCF Valuation'!$E$39 | C7: =((1*'DCF Valuation'!$E$24/(1+C$6)^1+1*'DCF Valuation'!$F$24/(1+C$6)^2+1*'DCF Valuation'!$G$24/(1+C$6)^3+(1*'DCF Valuation'!$G$24*(1+$A7)/(C$6-$A7))/(1+C$6)^3)+'DCF Valuation'!$E$35)/'DCF Valuation'!$E$39 | D7: =((1*'DCF Valuation'!$E$24/(1+D$6)^1+1*'DCF Valuation'!$F$24/(1+D$6)^2+1*'DCF Valuation'!$G$24/(1+D$6)^3+(1*'DCF Valuation'!$G$24*(1+$A7)/(D$6-$A7))/(1+D$6)^3)+'DCF Valuation'!$E$35)/'DCF Valuation'!$E$39 | E7: =((1*'DCF Valuation'!$E$24/(1+E$6)^1+1*'DCF Valuation'!$F$24/(1+E$6)^2+1*'DCF Valuation'!$G$24/(1+E$6)^3+(1*'DCF Valuation'!$G$24*(1+$A7)/(E$6-$A7))/(1+E$6)^3)+'DCF Valuation'!$E$35)/'DCF Valuation'!$E$39 | F7: =((1*'DCF Valuation'!$E$24/(1+F$6)^1+1*'DCF Valuation'!$F$24/(1+F$6)^2+1*'DCF Valuation'!$G$24/(1+F$6)^3+(1*'DCF Valuation'!$G$24*(1+$A7)/(F$6-$A7))/(1+F$6)^3)+'DCF Valuation'!$E$35)/'DCF Valuation'!$E$39
A8: ='DCF Valuation'!$E$16-0.01 | B8: =((1*'DCF Valuation'!$E$24/(1+B$6)^1+1*'DCF Valuation'!$F$24/(1+B$6)^2+1*'DCF Valuation'!$G$24/(1+B$6)^3+(1*'DCF Valuation'!$G$24*(1+$A8)/(B$6-$A8))/(1+B$6)^3)+'DCF Valuation'!$E$35)/'DCF Valuation'!$E$39 | C8: =((1*'DCF Valuation'!$E$24/(1+C$6)^1+1*'DCF Valuation'!$F$24/(1+C$6)^2+1*'DCF Valuation'!$G$24/(1+C$6)^3+(1*'DCF Valuation'!$G$24*(1+$A8)/(C$6-$A8))/(1+C$6)^3)+'DCF Valuation'!$E$35)/'DCF Valuation'!$E$39 | D8: =((1*'DCF Valuation'!$E$24/(1+D$6)^1+1*'DCF Valuation'!$F$24/(1+D$6)^2+1*'DCF Valuation'!$G$24/(1+D$6)^3+(1*'DCF Valuation'!$G$24*(1+$A8)/(D$6-$A8))/(1+D$6)^3)+'DCF Valuation'!$E$35)/'DCF Valuation'!$E$39 | E8: =((1*'DCF Valuation'!$E$24/(1+E$6)^1+1*'DCF Valuation'!$F$24/(1+E$6)^2+1*'DCF Valuation'!$G$24/(1+E$6)^3+(1*'DCF Valuation'!$G$24*(1+$A8)/(E$6-$A8))/(1+E$6)^3)+'DCF Valuation'!$E$35)/'DCF Valuation'!$E$39 | F8: =((1*'DCF Valuation'!$E$24/(1+F$6)^1+1*'DCF Valuation'!$F$24/(1+F$6)^2+1*'DCF Valuation'!$G$24/(1+F$6)^3+(1*'DCF Valuation'!$G$24*(1+$A8)/(F$6-$A8))/(1+F$6)^3)+'DCF Valuation'!$E$35)/'DCF Valuation'!$E$39
A9: ='DCF Valuation'!$E$16+0.0 | B9: =((1*'DCF Valuation'!$E$24/(1+B$6)^1+1*'DCF Valuation'!$F$24/(1+B$6)^2+1*'DCF Valuation'!$G$24/(1+B$6)^3+(1*'DCF Valuation'!$G$24*(1+$A9)/(B$6-$A9))/(1+B$6)^3)+'DCF Valuation'!$E$35)/'DCF Valuation'!$E$39 | C9: =((1*'DCF Valuation'!$E$24/(1+C$6)^1+1*'DCF Valuation'!$F$24/(1+C$6)^2+1*'DCF Valuation'!$G$24/(1+C$6)^3+(1*'DCF Valuation'!$G$24*(1+$A9)/(C$6-$A9))/(1+C$6)^3)+'DCF Valuation'!$E$35)/'DCF Valuation'!$E$39 | D9: =((1*'DCF Valuation'!$E$24/(1+D$6)^1+1*'DCF Valuation'!$F$24/(1+D$6)^2+1*'DCF Valuation'!$G$24/(1+D$6)^3+(1*'DCF Valuation'!$G$24*(1+$A9)/(D$6-$A9))/(1+D$6)^3)+'DCF Valuation'!$E$35)/'DCF Valuation'!$E$39 | E9: =((1*'DCF Valuation'!$E$24/(1+E$6)^1+1*'DCF Valuation'!$F$24/(1+E$6)^2+1*'DCF Valuation'!$G$24/(1+E$6)^3+(1*'DCF Valuation'!$G$24*(1+$A9)/(E$6-$A9))/(1+E$6)^3)+'DCF Valuation'!$E$35)/'DCF Valuation'!$E$39 | F9: =((1*'DCF Valuation'!$E$24/(1+F$6)^1+1*'DCF Valuation'!$F$24/(1+F$6)^2+1*'DCF Valuation'!$G$24/(1+F$6)^3+(1*'DCF Valuation'!$G$24*(1+$A9)/(F$6-$A9))/(1+F$6)^3)+'DCF Valuation'!$E$35)/'DCF Valuation'!$E$39
A10: ='DCF Valuation'!$E$16+0.01 | B10: =((1*'DCF Valuation'!$E$24/(1+B$6)^1+1*'DCF Valuation'!$F$24/(1+B$6)^2+1*'DCF Valuation'!$G$24/(1+B$6)^3+(1*'DCF Valuation'!$G$24*(1+$A10)/(B$6-$A10))/(1+B$6)^3)+'DCF Valuation'!$E$35)/'DCF Valuation'!$E$39 | C10: =((1*'DCF Valuation'!$E$24/(1+C$6)^1+1*'DCF Valuation'!$F$24/(1+C$6)^2+1*'DCF Valuation'!$G$24/(1+C$6)^3+(1*'DCF Valuation'!$G$24*(1+$A10)/(C$6-$A10))/(1+C$6)^3)+'DCF Valuation'!$E$35)/'DCF Valuation'!$E$39 | D10: =((1*'DCF Valuation'!$E$24/(1+D$6)^1+1*'DCF Valuation'!$F$24/(1+D$6)^2+1*'DCF Valuation'!$G$24/(1+D$6)^3+(1*'DCF Valuation'!$G$24*(1+$A10)/(D$6-$A10))/(1+D$6)^3)+'DCF Valuation'!$E$35)/'DCF Valuation'!$E$39 | E10: =((1*'DCF Valuation'!$E$24/(1+E$6)^1+1*'DCF Valuation'!$F$24/(1+E$6)^2+1*'DCF Valuation'!$G$24/(1+E$6)^3+(1*'DCF Valuation'!$G$24*(1+$A10)/(E$6-$A10))/(1+E$6)^3)+'DCF Valuation'!$E$35)/'DCF Valuation'!$E$39 | F10: =((1*'DCF Valuation'!$E$24/(1+F$6)^1+1*'DCF Valuation'!$F$24/(1+F$6)^2+1*'DCF Valuation'!$G$24/(1+F$6)^3+(1*'DCF Valuation'!$G$24*(1+$A10)/(F$6-$A10))/(1+F$6)^3)+'DCF Valuation'!$E$35)/'DCF Valuation'!$E$39
A11: ='DCF Valuation'!$E$16+0.02 | B11: =((1*'DCF Valuation'!$E$24/(1+B$6)^1+1*'DCF Valuation'!$F$24/(1+B$6)^2+1*'DCF Valuation'!$G$24/(1+B$6)^3+(1*'DCF Valuation'!$G$24*(1+$A11)/(B$6-$A11))/(1+B$6)^3)+'DCF Valuation'!$E$35)/'DCF Valuation'!$E$39 | C11: =((1*'DCF Valuation'!$E$24/(1+C$6)^1+1*'DCF Valuation'!$F$24/(1+C$6)^2+1*'DCF Valuation'!$G$24/(1+C$6)^3+(1*'DCF Valuation'!$G$24*(1+$A11)/(C$6-$A11))/(1+C$6)^3)+'DCF Valuation'!$E$35)/'DCF Valuation'!$E$39 | D11: =((1*'DCF Valuation'!$E$24/(1+D$6)^1+1*'DCF Valuation'!$F$24/(1+D$6)^2+1*'DCF Valuation'!$G$24/(1+D$6)^3+(1*'DCF Valuation'!$G$24*(1+$A11)/(D$6-$A11))/(1+D$6)^3)+'DCF Valuation'!$E$35)/'DCF Valuation'!$E$39 | E11: =((1*'DCF Valuation'!$E$24/(1+E$6)^1+1*'DCF Valuation'!$F$24/(1+E$6)^2+1*'DCF Valuation'!$G$24/(1+E$6)^3+(1*'DCF Valuation'!$G$24*(1+$A11)/(E$6-$A11))/(1+E$6)^3)+'DCF Valuation'!$E$35)/'DCF Valuation'!$E$39 | F11: =((1*'DCF Valuation'!$E$24/(1+F$6)^1+1*'DCF Valuation'!$F$24/(1+F$6)^2+1*'DCF Valuation'!$G$24/(1+F$6)^3+(1*'DCF Valuation'!$G$24*(1+$A11)/(F$6-$A11))/(1+F$6)^3)+'DCF Valuation'!$E$35)/'DCF Valuation'!$E$39
A13: GRID 2 — value/share vs PREMIUM ADT growth (FY27E lever)
A14: Premium ADT growth | B14: Value/share (Rs) | D14: Scales the derivatives share of revenue through to FCFF.
A15: =Assumptions!$H$8-0.3 | B15: =(((1+('Segment Revenue Build'!$E$7/'Segment Revenue Build'!$E$19)*((A15-Assumptions!$H$8)/(1+Assumptions!$H$8)))*'DCF Valuation'!$E$24/(1+'DCF Valuation'!$E$15)^1+(1+('Segment Revenue Build'!$E$7/'Segment Revenue Build'!$E$19)*((A15-Assumptions!$H$8)/(1+Assumptions!$H$8)))*'DCF Valuation'!$F$24/(1+'DCF Valuation'!$E$15)^2+(1+('Segment Revenue Build'!$E$7/'Segment Revenue Build'!$E$19)*((A15-Assumptions!$H$8)/(1+Assumptions!$H$8)))*'DCF Valuation'!$G$24/(1+'DCF Valuation'!$E$15)^3+((1+('Segment Revenue Build'!$E$7/'Segment Revenue Build'!$E$19)*((A15-Assumptions!$H$8)/(1+Assumptions!$H$8)))*'DCF Valuation'!$G$24*(1+'DCF Valuation'!$E$16)/('DCF Valuation'!$E$15-'DCF Valuation'!$E$16))/(1+'DCF Valuation'!$E$15)^3)+'DCF Valuation'!$E$35)/'DCF Valuation'!$E$39
A16: =Assumptions!$H$8-0.2 | B16: =(((1+('Segment Revenue Build'!$E$7/'Segment Revenue Build'!$E$19)*((A16-Assumptions!$H$8)/(1+Assumptions!$H$8)))*'DCF Valuation'!$E$24/(1+'DCF Valuation'!$E$15)^1+(1+('Segment Revenue Build'!$E$7/'Segment Revenue Build'!$E$19)*((A16-Assumptions!$H$8)/(1+Assumptions!$H$8)))*'DCF Valuation'!$F$24/(1+'DCF Valuation'!$E$15)^2+(1+('Segment Revenue Build'!$E$7/'Segment Revenue Build'!$E$19)*((A16-Assumptions!$H$8)/(1+Assumptions!$H$8)))*'DCF Valuation'!$G$24/(1+'DCF Valuation'!$E$15)^3+((1+('Segment Revenue Build'!$E$7/'Segment Revenue Build'!$E$19)*((A16-Assumptions!$H$8)/(1+Assumptions!$H$8)))*'DCF Valuation'!$G$24*(1+'DCF Valuation'!$E$16)/('DCF Valuation'!$E$15-'DCF Valuation'!$E$16))/(1+'DCF Valuation'!$E$15)^3)+'DCF Valuation'!$E$35)/'DCF Valuation'!$E$39
A17: =Assumptions!$H$8-0.1 | B17: =(((1+('Segment Revenue Build'!$E$7/'Segment Revenue Build'!$E$19)*((A17-Assumptions!$H$8)/(1+Assumptions!$H$8)))*'DCF Valuation'!$E$24/(1+'DCF Valuation'!$E$15)^1+(1+('Segment Revenue Build'!$E$7/'Segment Revenue Build'!$E$19)*((A17-Assumptions!$H$8)/(1+Assumptions!$H$8)))*'DCF Valuation'!$F$24/(1+'DCF Valuation'!$E$15)^2+(1+('Segment Revenue Build'!$E$7/'Segment Revenue Build'!$E$19)*((A17-Assumptions!$H$8)/(1+Assumptions!$H$8)))*'DCF Valuation'!$G$24/(1+'DCF Valuation'!$E$15)^3+((1+('Segment Revenue Build'!$E$7/'Segment Revenue Build'!$E$19)*((A17-Assumptions!$H$8)/(1+Assumptions!$H$8)))*'DCF Valuation'!$G$24*(1+'DCF Valuation'!$E$16)/('DCF Valuation'!$E$15-'DCF Valuation'!$E$16))/(1+'DCF Valuation'!$E$15)^3)+'DCF Valuation'!$E$35)/'DCF Valuation'!$E$39
A18: =Assumptions!$H$8+0.0 | B18: =(((1+('Segment Revenue Build'!$E$7/'Segment Revenue Build'!$E$19)*((A18-Assumptions!$H$8)/(1+Assumptions!$H$8)))*'DCF Valuation'!$E$24/(1+'DCF Valuation'!$E$15)^1+(1+('Segment Revenue Build'!$E$7/'Segment Revenue Build'!$E$19)*((A18-Assumptions!$H$8)/(1+Assumptions!$H$8)))*'DCF Valuation'!$F$24/(1+'DCF Valuation'!$E$15)^2+(1+('Segment Revenue Build'!$E$7/'Segment Revenue Build'!$E$19)*((A18-Assumptions!$H$8)/(1+Assumptions!$H$8)))*'DCF Valuation'!$G$24/(1+'DCF Valuation'!$E$15)^3+((1+('Segment Revenue Build'!$E$7/'Segment Revenue Build'!$E$19)*((A18-Assumptions!$H$8)/(1+Assumptions!$H$8)))*'DCF Valuation'!$G$24*(1+'DCF Valuation'!$E$16)/('DCF Valuation'!$E$15-'DCF Valuation'!$E$16))/(1+'DCF Valuation'!$E$15)^3)+'DCF Valuation'!$E$35)/'DCF Valuation'!$E$39
A19: =Assumptions!$H$8+0.1 | B19: =(((1+('Segment Revenue Build'!$E$7/'Segment Revenue Build'!$E$19)*((A19-Assumptions!$H$8)/(1+Assumptions!$H$8)))*'DCF Valuation'!$E$24/(1+'DCF Valuation'!$E$15)^1+(1+('Segment Revenue Build'!$E$7/'Segment Revenue Build'!$E$19)*((A19-Assumptions!$H$8)/(1+Assumptions!$H$8)))*'DCF Valuation'!$F$24/(1+'DCF Valuation'!$E$15)^2+(1+('Segment Revenue Build'!$E$7/'Segment Revenue Build'!$E$19)*((A19-Assumptions!$H$8)/(1+Assumptions!$H$8)))*'DCF Valuation'!$G$24/(1+'DCF Valuation'!$E$15)^3+((1+('Segment Revenue Build'!$E$7/'Segment Revenue Build'!$E$19)*((A19-Assumptions!$H$8)/(1+Assumptions!$H$8)))*'DCF Valuation'!$G$24*(1+'DCF Valuation'!$E$16)/('DCF Valuation'!$E$15-'DCF Valuation'!$E$16))/(1+'DCF Valuation'!$E$15)^3)+'DCF Valuation'!$E$35)/'DCF Valuation'!$E$39
A20: =Assumptions!$H$8+0.2 | B20: =(((1+('Segment Revenue Build'!$E$7/'Segment Revenue Build'!$E$19)*((A20-Assumptions!$H$8)/(1+Assumptions!$H$8)))*'DCF Valuation'!$E$24/(1+'DCF Valuation'!$E$15)^1+(1+('Segment Revenue Build'!$E$7/'Segment Revenue Build'!$E$19)*((A20-Assumptions!$H$8)/(1+Assumptions!$H$8)))*'DCF Valuation'!$F$24/(1+'DCF Valuation'!$E$15)^2+(1+('Segment Revenue Build'!$E$7/'Segment Revenue Build'!$E$19)*((A20-Assumptions!$H$8)/(1+Assumptions!$H$8)))*'DCF Valuation'!$G$24/(1+'DCF Valuation'!$E$15)^3+((1+('Segment Revenue Build'!$E$7/'Segment Revenue Build'!$E$19)*((A20-Assumptions!$H$8)/(1+Assumptions!$H$8)))*'DCF Valuation'!$G$24*(1+'DCF Valuation'!$E$16)/('DCF Valuation'!$E$15-'DCF Valuation'!$E$16))/(1+'DCF Valuation'!$E$15)^3)+'DCF Valuation'!$E$35)/'DCF Valuation'!$E$39
A21: =Assumptions!$H$8+0.3 | B21: =(((1+('Segment Revenue Build'!$E$7/'Segment Revenue Build'!$E$19)*((A21-Assumptions!$H$8)/(1+Assumptions!$H$8)))*'DCF Valuation'!$E$24/(1+'DCF Valuation'!$E$15)^1+(1+('Segment Revenue Build'!$E$7/'Segment Revenue Build'!$E$19)*((A21-Assumptions!$H$8)/(1+Assumptions!$H$8)))*'DCF Valuation'!$F$24/(1+'DCF Valuation'!$E$15)^2+(1+('Segment Revenue Build'!$E$7/'Segment Revenue Build'!$E$19)*((A21-Assumptions!$H$8)/(1+Assumptions!$H$8)))*'DCF Valuation'!$G$24/(1+'DCF Valuation'!$E$15)^3+((1+('Segment Revenue Build'!$E$7/'Segment Revenue Build'!$E$19)*((A21-Assumptions!$H$8)/(1+Assumptions!$H$8)))*'DCF Valuation'!$G$24*(1+'DCF Valuation'!$E$16)/('DCF Valuation'!$E$15-'DCF Valuation'!$E$16))/(1+'DCF Valuation'!$E$15)^3)+'DCF Valuation'!$E$35)/'DCF Valuation'!$E$39
A23: GRID 3 — value/share vs THE WEDGE (premium/notional ratio)
A24: Premium/notional | B24: Value/share (Rs) | C24: Levy impact (Rs cr) | E24: The wedge sets the SEBI levy: notional = premium / wedge. A LOWER wedge means a BIGGER notional base and a bigger levy for the same revenue.
A25: 0.00091491 | B25: =(((1-(C25*(1-Assumptions!$H$55))/'DCF Valuation'!$E$24)*'DCF Valuation'!$E$24/(1+'DCF Valuation'!$E$15)^1+(1-(C25*(1-Assumptions!$H$55))/'DCF Valuation'!$E$24)*'DCF Valuation'!$F$24/(1+'DCF Valuation'!$E$15)^2+(1-(C25*(1-Assumptions!$H$55))/'DCF Valuation'!$E$24)*'DCF Valuation'!$G$24/(1+'DCF Valuation'!$E$15)^3+((1-(C25*(1-Assumptions!$H$55))/'DCF Valuation'!$E$24)*'DCF Valuation'!$G$24*(1+'DCF Valuation'!$E$16)/('DCF Valuation'!$E$15-'DCF Valuation'!$E$16))/(1+'DCF Valuation'!$E$15)^3)+'DCF Valuation'!$E$35)/'DCF Valuation'!$E$39 | C25: =('Drivers & History'!$E$7/A25*Assumptions!$H$14)-'Income Statement'!$E$22
A26: 0.00095 | B26: =(((1-(C26*(1-Assumptions!$H$55))/'DCF Valuation'!$E$24)*'DCF Valuation'!$E$24/(1+'DCF Valuation'!$E$15)^1+(1-(C26*(1-Assumptions!$H$55))/'DCF Valuation'!$E$24)*'DCF Valuation'!$F$24/(1+'DCF Valuation'!$E$15)^2+(1-(C26*(1-Assumptions!$H$55))/'DCF Valuation'!$E$24)*'DCF Valuation'!$G$24/(1+'DCF Valuation'!$E$15)^3+((1-(C26*(1-Assumptions!$H$55))/'DCF Valuation'!$E$24)*'DCF Valuation'!$G$24*(1+'DCF Valuation'!$E$16)/('DCF Valuation'!$E$15-'DCF Valuation'!$E$16))/(1+'DCF Valuation'!$E$15)^3)+'DCF Valuation'!$E$35)/'DCF Valuation'!$E$39 | C26: =('Drivers & History'!$E$7/A26*Assumptions!$H$14)-'Income Statement'!$E$22
A27: 0.00104315 | B27: =(((1-(C27*(1-Assumptions!$H$55))/'DCF Valuation'!$E$24)*'DCF Valuation'!$E$24/(1+'DCF Valuation'!$E$15)^1+(1-(C27*(1-Assumptions!$H$55))/'DCF Valuation'!$E$24)*'DCF Valuation'!$F$24/(1+'DCF Valuation'!$E$15)^2+(1-(C27*(1-Assumptions!$H$55))/'DCF Valuation'!$E$24)*'DCF Valuation'!$G$24/(1+'DCF Valuation'!$E$15)^3+((1-(C27*(1-Assumptions!$H$55))/'DCF Valuation'!$E$24)*'DCF Valuation'!$G$24*(1+'DCF Valuation'!$E$16)/('DCF Valuation'!$E$15-'DCF Valuation'!$E$16))/(1+'DCF Valuation'!$E$15)^3)+'DCF Valuation'!$E$35)/'DCF Valuation'!$E$39 | C27: =('Drivers & History'!$E$7/A27*Assumptions!$H$14)-'Income Statement'!$E$22
A28: 0.00115 | B28: =(((1-(C28*(1-Assumptions!$H$55))/'DCF Valuation'!$E$24)*'DCF Valuation'!$E$24/(1+'DCF Valuation'!$E$15)^1+(1-(C28*(1-Assumptions!$H$55))/'DCF Valuation'!$E$24)*'DCF Valuation'!$F$24/(1+'DCF Valuation'!$E$15)^2+(1-(C28*(1-Assumptions!$H$55))/'DCF Valuation'!$E$24)*'DCF Valuation'!$G$24/(1+'DCF Valuation'!$E$15)^3+((1-(C28*(1-Assumptions!$H$55))/'DCF Valuation'!$E$24)*'DCF Valuation'!$G$24*(1+'DCF Valuation'!$E$16)/('DCF Valuation'!$E$15-'DCF Valuation'!$E$16))/(1+'DCF Valuation'!$E$15)^3)+'DCF Valuation'!$E$35)/'DCF Valuation'!$E$39 | C28: =('Drivers & History'!$E$7/A28*Assumptions!$H$14)-'Income Statement'!$E$22
A29: 0.00124959 | B29: =(((1-(C29*(1-Assumptions!$H$55))/'DCF Valuation'!$E$24)*'DCF Valuation'!$E$24/(1+'DCF Valuation'!$E$15)^1+(1-(C29*(1-Assumptions!$H$55))/'DCF Valuation'!$E$24)*'DCF Valuation'!$F$24/(1+'DCF Valuation'!$E$15)^2+(1-(C29*(1-Assumptions!$H$55))/'DCF Valuation'!$E$24)*'DCF Valuation'!$G$24/(1+'DCF Valuation'!$E$15)^3+((1-(C29*(1-Assumptions!$H$55))/'DCF Valuation'!$E$24)*'DCF Valuation'!$G$24*(1+'DCF Valuation'!$E$16)/('DCF Valuation'!$E$15-'DCF Valuation'!$E$16))/(1+'DCF Valuation'!$E$15)^3)+'DCF Valuation'!$E$35)/'DCF Valuation'!$E$39 | C29: =('Drivers & History'!$E$7/A29*Assumptions!$H$14)-'Income Statement'!$E$22
A30: Q2FY26 low = 0.091491% is ALREADY PRINTED inside this cycle.

Sheet Checks
A1: BSE Ltd — Model Integrity Checks
A2: Every row is a live formula compared against a disclosed actual. A model that cannot reproduce the audited past should not be used to forecast the future.
A3: Target values are typed (blue) from the research; Model values are formulas.
A5: Check | B5: Model | C5: Target | D5: Diff | E5: Status | F5: Note
A6: A. DOES THE MODEL REPRODUCE THE AUDITED PAST?
A7: FY26 revenue from operations | B7: ='Income Statement'!D7 | C7: 4833.95 | D7: =B7-C7 | E7: =IF(ABS(D7)<=2.0,"PASS","REVIEW") | F7: Audited consolidated [AR FY26 Note 22].
A8: FY26 derivatives txn charges | B8: ='Segment Revenue Build'!D7 | C8: 3134.37 | D8: =B8-C8 | E8: =IF(ABS(D8)<=1.0,"PASS","REVIEW") | F8: MD&A split (unaudited). 64.84% of consolidated revenue.
A9: FY26 transaction charges total | B9: ='Segment Revenue Build'!D12 | C9: 3669.48 | D9: =B9-C9 | E9: =IF(ABS(D9)<=1.0,"PASS","REVIEW") | F9: Sub-components tie exactly in the MD&A.
A10: FY26 SEBI regulatory fee | B10: ='Income Statement'!D22 | C10: 566.16 | D10: =B10-C10 | E10: =IF(ABS(D10)<=2.0,"PASS","REVIEW") | F10: Computed on NOTIONAL turnover.
A11: FY26 investment income | B11: ='Income Statement'!D8 | C11: 290.3 | D11: =B11-C11 | E11: =IF(ABS(D11)<=1.0,"PASS","REVIEW") | F11: = avg own corpus 4,885.84 x 5.942%.
A12: FY26 PAT attributable | B12: ='Income Statement'!D37 | C12: 2496.98 | D12: =B12-C12 | E12: =IF(ABS(D12)<=5.0,"PASS","REVIEW") | F12: Audited [AR FY26 Consolidated P&L].
A13: FY26 EPS (Rs) — issued-share basis | B13: ='Income Statement'!D38 | C13: 60.61 | D13: =B13-C13 | E13: =IF(ABS(D13)<=0.15,"PASS","REVIEW") | F13: 2,496.98 / 41.1979 issued shares = Rs60.61 [records/capital_structure.md].
A14: FY26 P/E at Rs3,409.80 (x) | B14: =Assumptions!$H$70/'Income Statement'!D38 | C14: 56.26 | D14: =B14-C14 | E14: =IF(ABS(D14)<=0.2,"PASS","REVIEW") | F14: 3,409.80 / 60.61 = 56.26x — the report's 'reported earnings' multiple.
A15: CDSL double-count guard (assoc profit x stake value) | B15: ='Income Statement'!E31*'DCF Valuation'!E36 | C15: 0 | D15: =B15-C15 | E15: =IF(ABS(D15)<=0.01,"PASS","REVIEW") | F15: MUST be zero: if both the earnings and the market value are non-zero the stake is counted twice [W5 constraint 4].
A16: B. INTERNAL CONSISTENCY
A17: Balance sheet balances — FY27E | B17: ='Balance Sheet'!E23 | C17: 0 | D17: =B17-C17 | E17: =IF(ABS(D17)<=0.5,"PASS","REVIEW") | F17: Assets - Equity & Liabilities must be zero.
A18: Balance sheet balances — FY28E | B18: ='Balance Sheet'!F23 | C18: 0 | D18: =B18-C18 | E18: =IF(ABS(D18)<=0.5,"PASS","REVIEW") | F18: Assets - Equity & Liabilities must be zero.
A19: Balance sheet balances — FY29E | B19: ='Balance Sheet'!G23 | C19: 0 | D19: =B19-C19 | E19: =IF(ABS(D19)<=0.5,"PASS","REVIEW") | F19: Assets - Equity & Liabilities must be zero.
A20: Cost floor is binding in FY27E (>0 means yes) | B20: ='Income Statement'!E20 | C20: 0 | D20: =B20-C20 | E20: =IF(ABS(D20)<=100000.0,"PASS","REVIEW") | F20: Informational: shows how much cost the ex-levy floor is holding in place.
A21: C. REALITY TESTS AGAINST Q1FY27 (the latest actual)
A22: FY27E revenue vs Q1FY27 annualised | B22: ='Income Statement'!E7 | C22: 6264.08 | D22: =B22-C22 | E22: =IF(ABS(D22)<=100000.0,"PASS","REVIEW") | F22: Q1FY27 revenue x4 = Rs6,264cr. If FY27E is far above this, the forecast needs defending: Q1FY27 revenue grew only +0.16% SEQUENTIALLY.
A23: FY27E total income vs Q1FY27 annualised | B23: ='Income Statement'!E10 | C23: 6826.88 | D23: =B23-C23 | E23: =IF(ABS(D23)<=100000.0,"PASS","REVIEW") | F23: 110.1% of the Q1FY27 profit increase was NON-OPERATING.
A24: D. IS THE GROWTH ASSUMPTION EVEN POSSIBLE?
A25: Two-exchange premium pool FY26 (Rs cr) | B25: 90468 | F25: DERIVED: BSE premium ADT 19,523 / share 21.58%.
A26: Implied pool FY29E (grown at pool growth) | B26: =B25*(1+Assumptions!$H$67)^3
A27: BSE premium ADT FY29E (model) | B27: ='Drivers & History'!G7
A28: IMPLIED BSE MARKET SHARE IN FY29E | B28: =B27/B26 | E28: =IF(B28>0.5,"IMPOSSIBLE?",IF(B28>0.35,"AGGRESSIVE","PLAUSIBLE")) | F28: FY26 actual share 21.58% (from 14.44%). Share cannot exceed 100% — if this prints above ~35% the growth assumption is a share-transfer bet, not a market bet.
A30: E. SIZED RISKS THE MODEL NOW CARRIES
A31: Wedge reversion to Q2FY26 low — revenue at risk (Rs cr) | B31: ='Segment Revenue Build'!D7*(1-0.00091491/0.00104315) | C31: 385.35 | F31: Research: Rs385.35cr. A level ALREADY PRINTED inside this cycle.
A32: Core SGF gap: policy vs charged (Rs cr) | B32: ='Segment Revenue Build'!D12*Assumptions!$H$32*Assumptions!$H$45-'Income Statement'!D23 | C32: 112.79 | F32: Rs112.79cr a year of permanent cash into a restricted fund, sourced only from a concall.
