Workbook
Name DCF_ValuePerShare: 'DCF Valuation'!$E$36
Name DCF_WACC: 'DCF Valuation'!$E$15
Name DCF_EnterpriseValue: 'DCF Valuation'!$E$32

Sheet Assumptions
A1: BSE Ltd — Model Assumptions & Drivers
A2: Every yellow cell is an editable input. Downstream tabs reference these cells only. Sources tagged from BSE research (AR = Annual Report, MD&A, SECONDARY = external).
A3: Units: Rs Crore unless marked. Percentages stored as decimals (0.15 = 15.0%). Bps stored as absolute (e.g. 2.50).
B4: Actual | E4: Projected
A5: Driver | B5: FY24 | C5: FY25 | D5: FY26 | E5: FY27E | F5: FY28E | G5: FY29E | H5: Source / basis
A6: 1. VOLUME DRIVERS — Average Daily Turnover (ADTO) & market share
A7: Equity derivatives premium ADTO (Rs cr) | B7: 3200 | C7: 6500 | D7: 12000 | E7: 15600 | F7: 19500 | G7: 23400 | H7: SECONDARY: BSE monthly volume disclosures; premium turnover. Editable seed.
A8: ADTO growth — derivatives (%) | E8: 0.3 | F8: 0.25 | G8: 0.2 | H8: KEY LEVER. Derivatives is the dominant swing factor (FY25->FY26 premium ADTO ~+85%).
A9: Equity cash ADTO (Rs cr) | B9: 6800 | C9: 7000 | D9: 7165 | E9: 7523 | F9: 7975 | G9: 8454 | H9: SECONDARY: BSE cash-market turnover. FY26 cash turnover rose ~2.4%.
A10: ADTO growth — cash (%) | E10: 0.05 | F10: 0.06 | G10: 0.06 | H10: Cash-market ADTO growth. Lower and steadier than derivatives.
A11: BSE derivatives market share vs NSE (%) | B11: 0.06 | C11: 0.12 | D11: 0.22 | E11: 0.26 | F11: 0.28 | G11: 0.29 | H11: KEY LEVER. BSE has taken derivatives share sharply. Treated as a lever, not a constant.
A12: 2. REALISATION — Take-rate on turnover per segment
A13: Derivatives take-rate (fraction of turnover) | E13: 0.0010448 | F13: 0.0010448 | G13: 0.0010448 | H13: = FY26 deriv txn 3134cr / (deriv ADTO 12000 x 250 days). ~0.1045%. SEBI pricing risk.
A14: Cash take-rate (fraction of turnover) | E14: 0.0001397 | F14: 0.0001397 | G14: 0.0001397 | H14: = FY26 cash txn 250cr / (cash ADTO 7165 x 250 days). ~0.01397%. Fell ~19.5% in FY26.
A15: Trading days per year | B15: 250 | C15: 250 | D15: 250 | E15: 250 | F15: 250 | G15: 250 | H15: Approx NSE/BSE trading days. Editable.
A16: 3. OTHER REVENUE DRIVERS (growth on prior year)
A17: StAR MF platform fees growth (%) | E17: 0.2 | F17: 0.18 | G17: 0.15 | H17: MF platform fees. FY26 +23%.
A18: Listing fees growth (%) | E18: 0.12 | F18: 0.11 | G18: 0.1 | H18: Linked to IPO/listings pipeline. FY26 +10%.
A19: Book building / IPO fees growth (%) | E19: 0.12 | F19: 0.1 | G19: 0.1 | H19: IPO processing fees. FY26 +9%.
A20: Data feed & index licensing growth (%) | E20: 0.15 | F20: 0.14 | G20: 0.12 | H20: Asia Index/S&P BSE + colocation. FY26 colocation +133%.
A21: Other operating income growth (%) | E21: 0.15 | F21: 0.12 | G21: 0.1 | H21: Residual other operating income.
A22: 4. INVESTMENT / TREASURY INCOME
A23: Investable corpus incl SGF (Rs cr) | B23: 4000 | C23: 4800 | D23: 5200 | E23: 5720 | F23: 6292 | G23: 6921 | H23: SECONDARY: own investable surplus + Core SGF corpus. Editable seed.
A24: Corpus growth (%) | E24: 0.1 | F24: 0.1 | G24: 0.1 | H24: Corpus reinvestment growth.
A25: Investment income yield (%) | E25: 0.056 | F25: 0.056 | G25: 0.056 | H25: Yield on treasury+SGF. FY26 inv income 290cr / ~5200cr corpus ~5.6%.
A26: 5. OPERATING COST DRIVERS (growth on prior year)
A27: Employee cost growth (%) | E27: 0.14 | F27: 0.12 | G27: 0.11 | H27: Employee benefits. FY26 +26%.
A28: Technology cost growth (%) | E28: 0.18 | F28: 0.15 | G28: 0.13 | H28: Tech/infra cost. FY26 +24%.
A29: SEBI regulatory fee (% of txn charges) | E29: 0.12 | F29: 0.12 | G29: 0.12 | H29: SEBI reg fee scales with turnover/txn charges. FY26 566cr on 3669cr txn ~15%; editable.
A30: Other admin cost growth (%) | E30: 0.1 | F30: 0.09 | G30: 0.08 | H30: Other administrative expenses.
A31: Clearing & settlement (% of txn charges) | E31: 0.08 | F31: 0.08 | G31: 0.08 | H31: ICCL clearing cost, scales with volume.
A32: 6. D&A, CAPEX, WORKING CAPITAL, TAX
A33: Capex (% of revenue) | E33: 0.08 | F33: 0.07 | G33: 0.06 | H33: Capex intensity. FY26 elevated (515cr) on data-centre build.
A34: D&A (% of opening net block) | E34: 0.22 | F34: 0.22 | G34: 0.22 | H34: Depreciation on PPE. Editable schedule driver.
A35: Receivable days (on revenue) | E35: 42 | F35: 42 | G35: 42 | H35: Trade receivable days. FY26 553cr / 4834cr rev ~42d.
A36: Other current liab (% of revenue) | E36: 1.1 | F36: 1.05 | G36: 1 | H36: Current liabilities incl clearing/settlement float scale with activity.
A37: Effective tax rate (%) | E37: 0.25 | F37: 0.25 | G37: 0.25 | H37: Effective tax. FY26 824cr / 3299cr PBT ~25%.
A38: Dividend payout (% of PAT) | E38: 0.13 | F38: 0.13 | G38: 0.13 | H38: Payout ratio. FY26 316cr / 2487cr PAT ~13%.
A39: 7. VALUATION — WACC build-up (CAPM) & terminal
A40: Risk-free rate (%) | E40: 0.07 | H40: SECONDARY: 10Y India G-sec ~7.0%. Editable single input (col E).
...

Sheet Income Statement
A1: BSE Ltd — Consolidated Income Statement
A2: FY24-FY26 actuals (blue). FY27E-FY29E projected via Assumptions + Segment build. Revenue links (green) from Segment Revenue Build.
A3: Units: Rs Crore. Consolidated basis.
B4: Actual | E4: Projected
A5: Rs Crore | B5: FY24 | C5: FY25 | D5: FY26 | E5: FY27E | F5: FY28E | G5: FY29E | H5: Source / formula basis
A6: INCOME
A7: Revenue from operations | B7: ='Segment Revenue Build'!B23 | C7: ='Segment Revenue Build'!C23 | D7: ='Segment Revenue Build'!D23 | E7: ='Segment Revenue Build'!E23 | F7: ='Segment Revenue Build'!F23 | G7: ='Segment Revenue Build'!G23 | H7: Link to Segment Revenue Build (consolidated line).
A8: Investment / treasury income | B8: ='Segment Revenue Build'!B21 | C8: ='Segment Revenue Build'!C21 | D8: ='Segment Revenue Build'!D21 | E8: ='Segment Revenue Build'!E21 | F8: ='Segment Revenue Build'!F21 | G8: ='Segment Revenue Build'!G21 | H8: Link to Segment Revenue Build investment income.
A9: Other income | B9: 25.4 | C9: 24.27 | D9: 23.85 | E9: =D9*(1+Assumptions!$E$21) | F9: =E9*(1+Assumptions!$F$21) | G9: =F9*(1+Assumptions!$G$21) | H9: Other income grown at other-op growth (Assumptions).
A10: Total income | B10: =B7+B8+B9 | C10: =C7+C8+C9 | D10: =D7+D8+D9 | E10: =E7+E8+E9 | F10: =F7+F8+F9 | G10: =G7+G8+G9 | H10: Revenue + investment income + other income.
A11: EXPENSES
A12: Employee benefits expense | B12: 204.71 | C12: 236.62 | D12: 297.81 | E12: =D12*(1+Assumptions!$E$27) | F12: =E12*(1+Assumptions!$F$27) | G12: =F12*(1+Assumptions!$G$27) | H12: Prior x (1 + employee growth).
A13: Technology & other operating expense | B13: 137.44 | C13: 164.29 | D13: 203.13 | E13: =D13*(1+Assumptions!$E$28) | F13: =E13*(1+Assumptions!$F$28) | G13: =F13*(1+Assumptions!$G$28) | H13: Prior x (1 + technology growth).
A14: SEBI / regulatory fees | B14: 169.77 | C14: 331.41 | D14: 566.16 | E14: ='Segment Revenue Build'!E12*Assumptions!$E$29 | F14: ='Segment Revenue Build'!F12*Assumptions!$F$29 | G14: ='Segment Revenue Build'!G12*Assumptions!$G$29 | H14: % of transaction charges (SEBI turnover fee). Link to Segment build.
A15: Clearing & settlement expense | B15: 133.14 | C15: 348.05 | D15: 280.35 | E15: ='Segment Revenue Build'!E12*Assumptions!$E$31 | F15: ='Segment Revenue Build'!F12*Assumptions!$F$31 | G15: ='Segment Revenue Build'!G12*Assumptions!$G$31 | H15: % of transaction charges. Link to Segment build.
A16: Core SGF contribution | B16: 91.7 | C16: 90 | D16: 76.96 | E16: =D16*(1+Assumptions!$E$30) | F16: =E16*(1+Assumptions!$F$30) | G16: =F16*(1+Assumptions!$G$30) | H16: Grown at admin growth (proxy).
A17: Other administrative expenses | B17: 338.84 | C17: 201.54 | D17: 247.32 | E17: =D17*(1+Assumptions!$E$30) | F17: =E17*(1+Assumptions!$F$30) | G17: =F17*(1+Assumptions!$G$30) | H17: Prior x (1 + admin growth).
A18: Depreciation & amortisation | B18: 95.44 | C18: 112.98 | D18: 158.96 | E18: ='Balance Sheet'!E9 | F18: ='Balance Sheet'!F9 | G18: ='Balance Sheet'!G9 | H18: Projected D&A links to Balance Sheet depreciation schedule.
A19: Total expenses | B19: =B12+B13+B14+B15+B16+B17+B18 | C19: =C12+C13+C14+C15+C16+C17+C18 | D19: =D12+D13+D14+D15+D16+D17+D18 | E19: =E12+E13+E14+E15+E16+E17+E18 | F19: =F12+F13+F14+F15+F16+F17+F18 | G19: =G12+G13+G14+G15+G16+G17+G18 | H19: Sum of expense lines (same-sheet).
A20: PROFIT
A21: EBITDA | B21: =B10-(B19-B18) | C21: =C10-(C19-C18) | D21: =D10-(D19-D18) | E21: =E10-(E19-E18) | F21: =F10-(F19-F18) | G21: =G10-(G19-G18) | H21: Total income - operating expenses ex-D&A.
A22: EBIT | B22: =B21-B18 | C22: =C21-C18 | D22: =D21-D18 | E22: =E21-E18 | F22: =F21-F18 | G22: =G21-G18 | H22: EBITDA - D&A.
A23: Finance cost | B23: 15.05 | C23: 0.03 | D23: 0.16 | E23: =Assumptions!$E$54 | F23: =Assumptions!$F$54 | G23: =Assumptions!$G$54 | H23: BSE effectively debt-free; references Assumptions (default 0).
A24: Share of associate profit (CDSL) | B24: 71.82 | C24: 82.59 | D24: 65.42 | E24: =D24*(1+Assumptions!$E$30) | F24: =E24*(1+Assumptions!$F$30) | G24: =F24*(1+Assumptions!$G$30) | H24: Associate (CDSL) equity-method profit; grown modestly.
A25: Exceptional items | B25: 406.62 | C25: 0 | D25: 0 | E25: =Assumptions!$E$55 | F25: =Assumptions!$F$55 | G25: =Assumptions!$G$55 | H25: Non-recurring; references Assumptions (default 0).
A26: Profit before tax | B26: =B22-B23+B24+B25 | C26: =C22-C23+C24+C25 | D26: =D22-D23+D24+D25 | E26: =E22-E23+E24+E25 | F26: =F22-F23+F24+F25 | G26: =G22-G23+G24+G25 | H26: EBIT - finance cost + associate + exceptional.
A27: Tax expense | B27: 223.86 | C27: 431.21 | D27: 823.84 | E27: =E26*Assumptions!$E$37 | F27: =F26*Assumptions!$F$37 | G27: =G26*Assumptions!$G$37 | H27: PBT x effective tax rate (Assumptions).
A28: Profit after tax (total) | B28: =B26-B27 | C28: =C26-C27 | D28: =D26-D27 | E28: =E26-E27 | F28: =F26-F27 | G28: =G26-G27 | H28: PBT - tax.
A29: EPS (Rs) | B29: =B28/Assumptions!$E$49 | C29: =C28/Assumptions!$E$49 | D29: =D28/Assumptions!$E$49 | E29: =E28/Assumptions!$E$49 | F29: =F28/Assumptions!$E$49 | G29: =G28/Assumptions!$E$49 | H29: PAT / shares outstanding (Assumptions).
A30: Dividend declared | B30: =B28*Assumptions!$E$38 | C30: =C28*Assumptions!$E$38 | D30: =D28*Assumptions!$E$38 | E30: =E28*Assumptions!$E$38 | F30: =F28*Assumptions!$E$38 | G30: =G28*Assumptions!$E$38 | H30: PAT x payout ratio (Assumptions).
A31: MARGINS & CHECKS
A32: EBITDA margin (% of total income) | B32: =B21/B10 | C32: =C21/C10 | D32: =D21/D10 | E32: =E21/E10 | F32: =F21/F10 | G32: =G21/G10
A33: PAT margin (% of total income) | B33: =B28/B10 | C33: =C28/C10 | D33: =D28/D10 | E33: =E28/E10 | F33: =F28/F10 | G33: =G28/G10

Sheet Balance Sheet
A1: BSE Ltd — Consolidated Balance Sheet
A2: FY24-FY26 actuals (blue). FY27E-FY29E projected. Retained earnings link (green) to Income Statement PAT & dividend. Capex/D&A schedule drives net block.
A3: Units: Rs Crore. Consolidated basis. Balance check row must equal 0.
B4: Actual | E4: Projected
A5: Rs Crore | B5: FY24 | C5: FY25 | D5: FY26 | E5: FY27E | F5: FY28E | G5: FY29E | H5: Source / formula basis
A6: CAPEX & DEPRECIATION SCHEDULE
A7: Net block — opening | E7: =D10 | F7: =E10 | G7: =F10
A8: Capex | B8: 131.32 | C8: 153.23 | D8: 515.16 | E8: ='Income Statement'!E7*Assumptions!$E$33 | F8: ='Income Statement'!F7*Assumptions!$F$33 | G8: ='Income Statement'!G7*Assumptions!$G$33 | H8: Projected = revenue x capex% (Assumptions). Hist = cash-flow capex.
A9: Depreciation & amortisation | B9: 95.44 | C9: 112.98 | D9: 158.96 | E9: =E7*Assumptions!$E$34 | F9: =F7*Assumptions!$F$34 | G9: =G7*Assumptions!$G$34 | H9: Projected = opening net block x D&A% (Assumptions).
A10: Net block — closing (PPE + CWIP) | B10: 209.54 | C10: 262.9 | D10: 595.14 | E10: =E7+E8-E9 | F10: =F7+F8-F9 | G10: =G7+G8-G9 | H10: Opening + capex - D&A. Hist = PPE + CWIP actual.
A11: ASSETS
A12: Other non-current assets | B12: 3270.78 | C12: 2736.09 | D12: 4633.86 | E12: =D12*(1+Assumptions!$E$24) | F12: =E12*(1+Assumptions!$F$24) | G12: =F12*(1+Assumptions!$G$24) | H12: Investments/other NCA grown at corpus growth.
A13: Total non-current assets | B13: =B10+B12 | C13: =C10+C12 | D13: =D10+D12 | E13: =E10+E12 | F13: =F10+F12 | G13: =G10+G12
A14: Trade receivables | B14: 210.87 | C14: 309.67 | D14: 553.16 | E14: ='Income Statement'!E7*Assumptions!$E$35/365 | F14: ='Income Statement'!F7*Assumptions!$F$35/365 | G14: ='Income Statement'!G7*Assumptions!$G$35/365 | H14: Projected = revenue x receivable days / 365.
A15: Other current assets (ex-cash) | B15: 3684.52 | C15: 5508.83 | D15: 6017.56 | E15: =D15*(1+Assumptions!$E$24) | F15: =E15*(1+Assumptions!$F$24) | G15: =F15*(1+Assumptions!$G$24) | H15: Other current assets grown at corpus growth.
A16: Cash & investments (balancing) | B16: 2074.52 | C16: 1524.16 | D16: 1646.42 | E16: =E23-E13-E14-E15 | F16: =F23-F13-F14-F15 | G16: =G23-G13-G14-G15 | H16: Projected = balancing plug: total E&L - non-cash assets (guarantees BS balances).
A17: Total current assets | B17: =B14+B15+B16 | C17: =C14+C15+C16 | D17: =D14+D15+D16 | E17: =E14+E15+E16 | F17: =F14+F15+F16 | G17: =G14+G15+G16
A18: TOTAL ASSETS | B18: =B13+B17 | C18: =C13+C17 | D18: =D13+D17 | E18: =E13+E17 | F18: =F13+F17 | G18: =G13+G17
A19: EQUITY & LIABILITIES
A20: Total equity | B20: 3454.66 | C20: 4575.7 | D20: 6795.5 | E20: =D20+'Income Statement'!E28-'Income Statement'!E30 | F20: =E20+'Income Statement'!F28-'Income Statement'!F30 | G20: =F20+'Income Statement'!G28-'Income Statement'!G30 | H20: Prior equity + PAT - dividend (retained earnings roll-forward). Link to IS.
A21: Non-current liabilities | B21: 13.63 | C21: 18.72 | D21: 33.32 | E21: =D21*(1+Assumptions!$E$30) | F21: =E21*(1+Assumptions!$F$30) | G21: =F21*(1+Assumptions!$G$30) | H21: Small; grown at admin growth.
A22: Current liabilities | B22: 5981.94 | C22: 5747.23 | D22: 6617.32 | E22: ='Income Statement'!E7*Assumptions!$E$36 | F22: ='Income Statement'!F7*Assumptions!$F$36 | G22: ='Income Statement'!G7*Assumptions!$G$36 | H22: Projected = revenue x current-liab% (Assumptions). Incl clearing/settlement float.
A23: TOTAL EQUITY & LIABILITIES | B23: =B20+B21+B22 | C23: =C20+C21+C22 | D23: =D20+D21+D22 | E23: =E20+E21+E22 | F23: =F20+F21+F22 | G23: =G20+G21+G22
A24: Balance check (Assets - E&L) | B24: =B18-B23 | C24: =C18-C23 | D24: =D18-D23 | E24: =E18-E23 | F24: =F18-F23 | G24: =G18-G23 | H24: Must be ~0 for projected years (plug via cash). Hist may differ (actuals).

Sheet Segment Revenue Build
A1: BSE Ltd — Segment Revenue Build
A2: Revenue disaggregated by segment. Historical = STANDALONE MD&A split (the only disclosed granularity), flagged. Projected = driver formulas referencing Assumptions.
A3: Units: Rs Crore. Transaction charges = ADTO x trading days x yield(bps)/10000. Historical actuals in blue.
B4: Actual | E4: Projected
A5: Rs Crore | B5: FY24 | C5: FY25 | D5: FY26 | E5: FY27E | F5: FY28E | G5: FY29E | H5: Source / formula basis
A6: TRANSACTION CHARGES
A7: Equity derivatives txn charges | C7: 1415.54 | D7: 3134.37 | E7: =Assumptions!$E$7*Assumptions!$E$15*Assumptions!$E$13 | F7: =Assumptions!$F$7*Assumptions!$F$15*Assumptions!$F$13 | G7: =Assumptions!$G$7*Assumptions!$G$15*Assumptions!$G$13 | H7: = deriv ADTO x days x yield(bps)/10000. ADTO & yield from Assumptions.
A8: Equity cash txn charges | C8: 303.56 | D8: 250.21 | E8: =Assumptions!$E$9*Assumptions!$E$15*Assumptions!$E$14 | F8: =Assumptions!$F$9*Assumptions!$F$15*Assumptions!$F$14 | G8: =Assumptions!$G$9*Assumptions!$G$15*Assumptions!$G$14 | H8: = cash ADTO x days x yield(bps)/10000.
A9: Currency derivatives txn charges | B9: 0 | C9: 0 | D9: 0 | E9: =Assumptions!$E$52 | F9: =Assumptions!$F$52 | G9: =Assumptions!$G$52 | H9: NOT-DISCLOSED in MD&A split -> AR audited Note 22. References Assumptions (default 0).
A10: SLB (securities lending) txn charges | B10: 0 | C10: 0 | D10: 0 | E10: =Assumptions!$E$53 | F10: =Assumptions!$F$53 | G10: =Assumptions!$G$53 | H10: NOT-DISCLOSED separately -> AR audited Note 22. References Assumptions (default 0).
A11: StAR MF platform fees | C11: 230.77 | D11: 284.9 | E11: =D11*(1+Assumptions!$E$17) | F11: =E11*(1+Assumptions!$F$17) | G11: =F11*(1+Assumptions!$G$17) | H11: = prior x (1 + StAR MF growth). MF platform, part of txn charges line.
A12: Transaction charges — total | C12: =C7+C8+C9+C10+C11 | D12: =D7+D8+D9+D10+D11 | E12: =E7+E8+E9+E10+E11 | F12: =F7+F8+F9+F10+F11 | G12: =G7+G8+G9+G10+G11 | H12: Sum of components (same-sheet).
A13: NON-TRANSACTION REVENUE
A14: Listing fees (annual + processing) | C14: 353.28 | D14: 388.61 | E14: =D14*(1+Assumptions!$E$18) | F14: =E14*(1+Assumptions!$F$18) | G14: =F14*(1+Assumptions!$G$18) | H14: = prior x (1 + listing growth). Linked to IPO/listings pipeline.
A15: Book building / IPO fees | C15: 95.36 | D15: 104.12 | E15: =D15*(1+Assumptions!$E$19) | F15: =E15*(1+Assumptions!$F$19) | G15: =F15*(1+Assumptions!$G$19) | H15: = prior x (1 + book-building growth).
A16: Data feed & index licensing income | C16: 72.62 | D16: 168.99 | E16: =D16*(1+Assumptions!$E$20) | F16: =E16*(1+Assumptions!$F$20) | G16: =F16*(1+Assumptions!$G$20) | H16: Asia Index/S&P BSE + colocation/data feed. = prior x (1 + data growth).
A17: Other operating income (residual) | C17: 95.44 | D17: 112.11 | E17: =D17*(1+Assumptions!$E$21) | F17: =E17*(1+Assumptions!$F$21) | G17: =F17*(1+Assumptions!$G$21) | H17: Other operating income less colocation (moved to data line).
A18: REVENUE FROM OPERATIONS (recomputed)
A19: Revenue from operations (build) | B19: =B12+B14+B15+B16+B17 | C19: =C12+C14+C15+C16+C17 | D19: =D12+D14+D15+D16+D17 | E19: =E12+E14+E15+E16+E17 | F19: =F12+F14+F15+F16+F17 | G19: =G12+G14+G15+G16+G17 | H19: Sum of all segment lines (same-sheet). Feeds Income Statement.
A20: INVESTMENT / TREASURY INCOME
A21: Investment / treasury income | B21: 202.47 | C21: 254.7 | D21: 290.3 | E21: =Assumptions!$E$23*Assumptions!$E$25 | F21: =Assumptions!$F$23*Assumptions!$F$25 | G21: =Assumptions!$G$23*Assumptions!$G$25 | H21: = investable corpus (incl SGF) x investment yield. From Assumptions.
A22: Consolidation scalar (consol/standalone) | C22: =2957.34/C19 | D22: =4833.95/D19 | E22: =$D$22 | F22: =$D$22 | G22: =$D$22 | H22: Consol rev / standalone-build rev. FY24 build undisclosed so scalar blank.
A23: Revenue from operations (consolidated) | B23: 1390.03 | C23: =C19*C22 | D23: =D19*D22 | E23: =E19*E22 | F23: =F19*F22 | G23: =G19*G22 | H23: FY24 = direct consolidated actual (no split disclosed). FY25-FY29 = build x consolidation scalar. Feeds Income Statement.

Sheet DCF Valuation
A1: BSE Ltd — DCF Valuation (FCFF)
A2: FCFF discounted at WACC (CAPM cost of equity + after-tax cost of debt). Terminal value via Gordon growth. All lines are formula chains referencing Assumptions and the Income Statement / Balance Sheet.
A3: Units: Rs Crore unless marked. BSE is a fee-income business (not a bank) so FCFF DCF applies.
A5: WACC BUILD-UP (CAPM)
A6: Risk-free rate | E6: =Assumptions!$E$40 | H6: From Assumptions (green).
A7: Equity risk premium | E7: =Assumptions!$E$41 | H7: From Assumptions.
A8: Beta (levered) | E8: =Assumptions!$E$42 | H8: From Assumptions.
A9: Cost of equity (CAPM) | E9: =E6+E8*E7 | H9: = Rf + beta x ERP (same-sheet).
A10: Pre-tax cost of debt | E10: =Assumptions!$E$43 | H10: From Assumptions.
A11: Tax rate | E11: =Assumptions!$E$37 | H11: From Assumptions.
A12: After-tax cost of debt | E12: =E10*(1-E11) | H12: = Kd x (1 - tax).
A13: Weight — equity | E13: =Assumptions!$E$44 | H13: From Assumptions.
A14: Weight — debt | E14: =Assumptions!$E$45 | H14: From Assumptions.
A15: WACC | E15: =E13*E9+E14*E12 | H15: = We x Ke + Wd x Kd(after tax).
A16: Terminal growth | E16: =Assumptions!$E$46 | H16: From Assumptions.
A17: FREE CASH FLOW TO FIRM (FCFF)
A18: EBIT | E18: ='Income Statement'!E22 | F18: ='Income Statement'!F22 | G18: ='Income Statement'!G22 | H18: Link to Income Statement EBIT.
A19: NOPAT = EBIT x (1 - tax) | E19: =E18*(1-Assumptions!$E$37) | F19: =F18*(1-Assumptions!$F$37) | G19: =G18*(1-Assumptions!$G$37) | H19: EBIT x (1 - tax rate from Assumptions).
A20: add: D&A | E20: ='Balance Sheet'!E9 | F20: ='Balance Sheet'!F9 | G20: ='Balance Sheet'!G9 | H20: Link to Balance Sheet D&A schedule.
A21: less: Capex | E21: =-'Balance Sheet'!E8 | F21: =-'Balance Sheet'!F8 | G21: =-'Balance Sheet'!G8 | H21: Link to Balance Sheet capex (negative).
A22: less: Increase in operating working capital | E22: =-('Balance Sheet'!E14-'Balance Sheet'!D14) | F22: =-('Balance Sheet'!F14-'Balance Sheet'!E14) | G22: =-('Balance Sheet'!G14-'Balance Sheet'!F14) | H22: Negative change in trade receivables (settlement float excluded). Link to BS.
A23: FCFF | E23: =E19+E20+E21+E22 | F23: =F19+F20+F21+F22 | G23: =G19+G20+G21+G22 | H23: NOPAT + D&A - Capex - dNWC.
A24: DISCOUNTING
A25: Discount period (years) | E25: =1 | F25: =2 | G25: =3 | H25: 1, 2, 3 ...
A26: Discount factor | E26: =1/(1+$E$15)^E25 | F26: =1/(1+$E$15)^F25 | G26: =1/(1+$E$15)^G25 | H26: = 1 / (1 + WACC)^period.
A27: PV of FCFF | E27: =E23*E26 | F27: =F23*F26 | G27: =G23*G26 | H27: FCFF x discount factor.
A28: TERMINAL VALUE & ENTERPRISE VALUE
A29: Terminal value (Gordon) | E29: =G23*(1+$E$16)/($E$15-$E$16) | H29: = FCFF(final) x (1+g) / (WACC - g).
A30: PV of terminal value | E30: =E29*G26 | H30: TV x final-year discount factor.
A31: Sum of PV of FCFF (explicit) | E31: =SUM(E27:G27) | H31: Sum of discounted explicit-period FCFF.
A32: Enterprise value | E32: =E31+E30 | H32: PV(explicit FCFF) + PV(terminal value).
A33: less: Net debt | E33: =Assumptions!$E$50 | H33: Net debt from Assumptions (negative = net cash).
A34: Equity value | E34: =E32-E33 | H34: EV - net debt.
A35: Shares outstanding (cr) | E35: =Assumptions!$E$49 | H35: From Assumptions.
A36: Implied value per share (Rs) | E36: =E34/E35 | H36: Equity value (Rs cr) / shares (cr) = Rs/share (both in crore units cancel).
A37: Current market price (Rs) | E37: =Assumptions!$E$48 | H37: From Assumptions.
A38: Implied upside / (downside) | E38: =E36/E37-1 | H38: Value per share / market price - 1.

Sheet Comps
A1: BSE Ltd — Trading Comparables
A2: Peer market data in blue (editable). Multiples and BSE-implied values are formulas. BSE fundamentals link (green) to Income Statement / DCF.
A3: Units: Rs Crore for values, Rs for price/share, x for multiples.
A5: Company | B5: Price (Rs) | C5: Shares (cr) | D5: Mkt cap | E5: Net debt | F5: EV | G5: PAT | I5: EBITDA | J5: Book value
A6: MCX | B6: 6500 | C6: 5.1 | D6: =B6*C6 | E6: -900 | F6: =D6+E6 | G6: 560 | I6: 700 | J6: 1600
A7: CDSL | B7: 1500 | C7: 20.9 | D7: =B7*C7 | E7: -1200 | F7: =D7+E7 | G7: 620 | I7: 800 | J7: 2000
A9: MULTIPLES (x)
A10: Company | B10: EV/EBITDA | C10: P/E | D10: P/B
A11: MCX | B11: =F6/I6 | C11: =D6/G6 | D11: =D6/J6
A12: CDSL | B12: =F7/I7 | C12: =D7/G7 | D12: =D7/J7
A13: Peer average | B13: =AVERAGE(B11:B12) | C13: =AVERAGE(C11:C12) | D13: =AVERAGE(D11:D12)
A15: BSE — IMPLIED VALUE FROM PEER MULTIPLES
A16: BSE EBITDA (FY26) | B16: ='Income Statement'!D21
A17: BSE PAT (FY26) | B17: ='Income Statement'!D28
A18: BSE book value (equity, FY26) | B18: ='Balance Sheet'!D20
A19: BSE net debt | B19: =Assumptions!$E$50
A20: BSE shares (cr) | B20: =Assumptions!$E$49
A21: Implied price/share — EV/EBITDA (Rs) | B21: =(B13*B16-B19)/B20
A22: Implied price/share — P/E (Rs) | B22: =(C13*B17)/B20
A23: Implied price/share — P/B (Rs) | B23: =(D13*B18)/B20

Sheet Sensitivity
A1: BSE Ltd — Sensitivity Analysis
A2: Value per share sensitivity. Each grid cell recomputes value/share from the FCFF stream on the DCF sheet using the row/column driver — fully formula-driven, never typed.
A3: Units: Rs per share. Grid 1: WACC (columns) x terminal growth (rows). Grid 2: value vs derivatives ADTO growth.
A5: GRID 1 — Value/share: WACC (columns) x Terminal growth (rows)
A6: g \ WACC | B6: ='DCF Valuation'!$E$15-0.02 | C6: ='DCF Valuation'!$E$15-0.01 | D6: ='DCF Valuation'!$E$15+0.0 | E6: ='DCF Valuation'!$E$15+0.01 | F6: ='DCF Valuation'!$E$15+0.02
A7: ='DCF Valuation'!$E$16-0.02 | B7: =(('DCF Valuation'!$E$23/(1+B$6)^1+'DCF Valuation'!$F$23/(1+B$6)^2+'DCF Valuation'!$G$23/(1+B$6)^3+('DCF Valuation'!$G$23*(1+$A7)/(B$6-$A7))/(1+B$6)^3)-'DCF Valuation'!$E$33)/'DCF Valuation'!$E$35 | C7: =(('DCF Valuation'!$E$23/(1+C$6)^1+'DCF Valuation'!$F$23/(1+C$6)^2+'DCF Valuation'!$G$23/(1+C$6)^3+('DCF Valuation'!$G$23*(1+$A7)/(C$6-$A7))/(1+C$6)^3)-'DCF Valuation'!$E$33)/'DCF Valuation'!$E$35 | D7: =(('DCF Valuation'!$E$23/(1+D$6)^1+'DCF Valuation'!$F$23/(1+D$6)^2+'DCF Valuation'!$G$23/(1+D$6)^3+('DCF Valuation'!$G$23*(1+$A7)/(D$6-$A7))/(1+D$6)^3)-'DCF Valuation'!$E$33)/'DCF Valuation'!$E$35 | E7: =(('DCF Valuation'!$E$23/(1+E$6)^1+'DCF Valuation'!$F$23/(1+E$6)^2+'DCF Valuation'!$G$23/(1+E$6)^3+('DCF Valuation'!$G$23*(1+$A7)/(E$6-$A7))/(1+E$6)^3)-'DCF Valuation'!$E$33)/'DCF Valuation'!$E$35 | F7: =(('DCF Valuation'!$E$23/(1+F$6)^1+'DCF Valuation'!$F$23/(1+F$6)^2+'DCF Valuation'!$G$23/(1+F$6)^3+('DCF Valuation'!$G$23*(1+$A7)/(F$6-$A7))/(1+F$6)^3)-'DCF Valuation'!$E$33)/'DCF Valuation'!$E$35
A8: ='DCF Valuation'!$E$16-0.01 | B8: =(('DCF Valuation'!$E$23/(1+B$6)^1+'DCF Valuation'!$F$23/(1+B$6)^2+'DCF Valuation'!$G$23/(1+B$6)^3+('DCF Valuation'!$G$23*(1+$A8)/(B$6-$A8))/(1+B$6)^3)-'DCF Valuation'!$E$33)/'DCF Valuation'!$E$35 | C8: =(('DCF Valuation'!$E$23/(1+C$6)^1+'DCF Valuation'!$F$23/(1+C$6)^2+'DCF Valuation'!$G$23/(1+C$6)^3+('DCF Valuation'!$G$23*(1+$A8)/(C$6-$A8))/(1+C$6)^3)-'DCF Valuation'!$E$33)/'DCF Valuation'!$E$35 | D8: =(('DCF Valuation'!$E$23/(1+D$6)^1+'DCF Valuation'!$F$23/(1+D$6)^2+'DCF Valuation'!$G$23/(1+D$6)^3+('DCF Valuation'!$G$23*(1+$A8)/(D$6-$A8))/(1+D$6)^3)-'DCF Valuation'!$E$33)/'DCF Valuation'!$E$35 | E8: =(('DCF Valuation'!$E$23/(1+E$6)^1+'DCF Valuation'!$F$23/(1+E$6)^2+'DCF Valuation'!$G$23/(1+E$6)^3+('DCF Valuation'!$G$23*(1+$A8)/(E$6-$A8))/(1+E$6)^3)-'DCF Valuation'!$E$33)/'DCF Valuation'!$E$35 | F8: =(('DCF Valuation'!$E$23/(1+F$6)^1+'DCF Valuation'!$F$23/(1+F$6)^2+'DCF Valuation'!$G$23/(1+F$6)^3+('DCF Valuation'!$G$23*(1+$A8)/(F$6-$A8))/(1+F$6)^3)-'DCF Valuation'!$E$33)/'DCF Valuation'!$E$35
A9: ='DCF Valuation'!$E$16+0.0 | B9: =(('DCF Valuation'!$E$23/(1+B$6)^1+'DCF Valuation'!$F$23/(1+B$6)^2+'DCF Valuation'!$G$23/(1+B$6)^3+('DCF Valuation'!$G$23*(1+$A9)/(B$6-$A9))/(1+B$6)^3)-'DCF Valuation'!$E$33)/'DCF Valuation'!$E$35 | C9: =(('DCF Valuation'!$E$23/(1+C$6)^1+'DCF Valuation'!$F$23/(1+C$6)^2+'DCF Valuation'!$G$23/(1+C$6)^3+('DCF Valuation'!$G$23*(1+$A9)/(C$6-$A9))/(1+C$6)^3)-'DCF Valuation'!$E$33)/'DCF Valuation'!$E$35 | D9: =(('DCF Valuation'!$E$23/(1+D$6)^1+'DCF Valuation'!$F$23/(1+D$6)^2+'DCF Valuation'!$G$23/(1+D$6)^3+('DCF Valuation'!$G$23*(1+$A9)/(D$6-$A9))/(1+D$6)^3)-'DCF Valuation'!$E$33)/'DCF Valuation'!$E$35 | E9: =(('DCF Valuation'!$E$23/(1+E$6)^1+'DCF Valuation'!$F$23/(1+E$6)^2+'DCF Valuation'!$G$23/(1+E$6)^3+('DCF Valuation'!$G$23*(1+$A9)/(E$6-$A9))/(1+E$6)^3)-'DCF Valuation'!$E$33)/'DCF Valuation'!$E$35 | F9: =(('DCF Valuation'!$E$23/(1+F$6)^1+'DCF Valuation'!$F$23/(1+F$6)^2+'DCF Valuation'!$G$23/(1+F$6)^3+('DCF Valuation'!$G$23*(1+$A9)/(F$6-$A9))/(1+F$6)^3)-'DCF Valuation'!$E$33)/'DCF Valuation'!$E$35
A10: ='DCF Valuation'!$E$16+0.01 | B10: =(('DCF Valuation'!$E$23/(1+B$6)^1+'DCF Valuation'!$F$23/(1+B$6)^2+'DCF Valuation'!$G$23/(1+B$6)^3+('DCF Valuation'!$G$23*(1+$A10)/(B$6-$A10))/(1+B$6)^3)-'DCF Valuation'!$E$33)/'DCF Valuation'!$E$35 | C10: =(('DCF Valuation'!$E$23/(1+C$6)^1+'DCF Valuation'!$F$23/(1+C$6)^2+'DCF Valuation'!$G$23/(1+C$6)^3+('DCF Valuation'!$G$23*(1+$A10)/(C$6-$A10))/(1+C$6)^3)-'DCF Valuation'!$E$33)/'DCF Valuation'!$E$35 | D10: =(('DCF Valuation'!$E$23/(1+D$6)^1+'DCF Valuation'!$F$23/(1+D$6)^2+'DCF Valuation'!$G$23/(1+D$6)^3+('DCF Valuation'!$G$23*(1+$A10)/(D$6-$A10))/(1+D$6)^3)-'DCF Valuation'!$E$33)/'DCF Valuation'!$E$35 | E10: =(('DCF Valuation'!$E$23/(1+E$6)^1+'DCF Valuation'!$F$23/(1+E$6)^2+'DCF Valuation'!$G$23/(1+E$6)^3+('DCF Valuation'!$G$23*(1+$A10)/(E$6-$A10))/(1+E$6)^3)-'DCF Valuation'!$E$33)/'DCF Valuation'!$E$35 | F10: =(('DCF Valuation'!$E$23/(1+F$6)^1+'DCF Valuation'!$F$23/(1+F$6)^2+'DCF Valuation'!$G$23/(1+F$6)^3+('DCF Valuation'!$G$23*(1+$A10)/(F$6-$A10))/(1+F$6)^3)-'DCF Valuation'!$E$33)/'DCF Valuation'!$E$35
A11: ='DCF Valuation'!$E$16+0.02 | B11: =(('DCF Valuation'!$E$23/(1+B$6)^1+'DCF Valuation'!$F$23/(1+B$6)^2+'DCF Valuation'!$G$23/(1+B$6)^3+('DCF Valuation'!$G$23*(1+$A11)/(B$6-$A11))/(1+B$6)^3)-'DCF Valuation'!$E$33)/'DCF Valuation'!$E$35 | C11: =(('DCF Valuation'!$E$23/(1+C$6)^1+'DCF Valuation'!$F$23/(1+C$6)^2+'DCF Valuation'!$G$23/(1+C$6)^3+('DCF Valuation'!$G$23*(1+$A11)/(C$6-$A11))/(1+C$6)^3)-'DCF Valuation'!$E$33)/'DCF Valuation'!$E$35 | D11: =(('DCF Valuation'!$E$23/(1+D$6)^1+'DCF Valuation'!$F$23/(1+D$6)^2+'DCF Valuation'!$G$23/(1+D$6)^3+('DCF Valuation'!$G$23*(1+$A11)/(D$6-$A11))/(1+D$6)^3)-'DCF Valuation'!$E$33)/'DCF Valuation'!$E$35 | E11: =(('DCF Valuation'!$E$23/(1+E$6)^1+'DCF Valuation'!$F$23/(1+E$6)^2+'DCF Valuation'!$G$23/(1+E$6)^3+('DCF Valuation'!$G$23*(1+$A11)/(E$6-$A11))/(1+E$6)^3)-'DCF Valuation'!$E$33)/'DCF Valuation'!$E$35 | F11: =(('DCF Valuation'!$E$23/(1+F$6)^1+'DCF Valuation'!$F$23/(1+F$6)^2+'DCF Valuation'!$G$23/(1+F$6)^3+('DCF Valuation'!$G$23*(1+$A11)/(F$6-$A11))/(1+F$6)^3)-'DCF Valuation'!$E$33)/'DCF Valuation'!$E$35
A13: GRID 2 — Value/share vs derivatives ADTO growth (key volume lever)
A14: Deriv ADTO growth | B14: Value/share (Rs) | H14: Note: this grid re-scales FY27E FCFF by the ratio of the sensitised derivatives revenue to base, holding WACC & g at DCF base.
A15: =Assumptions!$E$8-0.15 | B15: =(((1+('Segment Revenue Build'!$E$7/'Segment Revenue Build'!$E$19)*((A15-Assumptions!$E$8)/(1+Assumptions!$E$8)))*'DCF Valuation'!$E$23/(1+'DCF Valuation'!$E$15)^1+(1+('Segment Revenue Build'!$E$7/'Segment Revenue Build'!$E$19)*((A15-Assumptions!$E$8)/(1+Assumptions!$E$8)))*'DCF Valuation'!$F$23/(1+'DCF Valuation'!$E$15)^2+(1+('Segment Revenue Build'!$E$7/'Segment Revenue Build'!$E$19)*((A15-Assumptions!$E$8)/(1+Assumptions!$E$8)))*'DCF Valuation'!$G$23/(1+'DCF Valuation'!$E$15)^3+((1+('Segment Revenue Build'!$E$7/'Segment Revenue Build'!$E$19)*((A15-Assumptions!$E$8)/(1+Assumptions!$E$8)))*'DCF Valuation'!$G$23*(1+'DCF Valuation'!$E$16)/('DCF Valuation'!$E$15-'DCF Valuation'!$E$16))/(1+'DCF Valuation'!$E$15)^3)-'DCF Valuation'!$E$33)/'DCF Valuation'!$E$35
A16: =Assumptions!$E$8-0.1 | B16: =(((1+('Segment Revenue Build'!$E$7/'Segment Revenue Build'!$E$19)*((A16-Assumptions!$E$8)/(1+Assumptions!$E$8)))*'DCF Valuation'!$E$23/(1+'DCF Valuation'!$E$15)^1+(1+('Segment Revenue Build'!$E$7/'Segment Revenue Build'!$E$19)*((A16-Assumptions!$E$8)/(1+Assumptions!$E$8)))*'DCF Valuation'!$F$23/(1+'DCF Valuation'!$E$15)^2+(1+('Segment Revenue Build'!$E$7/'Segment Revenue Build'!$E$19)*((A16-Assumptions!$E$8)/(1+Assumptions!$E$8)))*'DCF Valuation'!$G$23/(1+'DCF Valuation'!$E$15)^3+((1+('Segment Revenue Build'!$E$7/'Segment Revenue Build'!$E$19)*((A16-Assumptions!$E$8)/(1+Assumptions!$E$8)))*'DCF Valuation'!$G$23*(1+'DCF Valuation'!$E$16)/('DCF Valuation'!$E$15-'DCF Valuation'!$E$16))/(1+'DCF Valuation'!$E$15)^3)-'DCF Valuation'!$E$33)/'DCF Valuation'!$E$35
A17: =Assumptions!$E$8-0.05 | B17: =(((1+('Segment Revenue Build'!$E$7/'Segment Revenue Build'!$E$19)*((A17-Assumptions!$E$8)/(1+Assumptions!$E$8)))*'DCF Valuation'!$E$23/(1+'DCF Valuation'!$E$15)^1+(1+('Segment Revenue Build'!$E$7/'Segment Revenue Build'!$E$19)*((A17-Assumptions!$E$8)/(1+Assumptions!$E$8)))*'DCF Valuation'!$F$23/(1+'DCF Valuation'!$E$15)^2+(1+('Segment Revenue Build'!$E$7/'Segment Revenue Build'!$E$19)*((A17-Assumptions!$E$8)/(1+Assumptions!$E$8)))*'DCF Valuation'!$G$23/(1+'DCF Valuation'!$E$15)^3+((1+('Segment Revenue Build'!$E$7/'Segment Revenue Build'!$E$19)*((A17-Assumptions!$E$8)/(1+Assumptions!$E$8)))*'DCF Valuation'!$G$23*(1+'DCF Valuation'!$E$16)/('DCF Valuation'!$E$15-'DCF Valuation'!$E$16))/(1+'DCF Valuation'!$E$15)^3)-'DCF Valuation'!$E$33)/'DCF Valuation'!$E$35
A18: =Assumptions!$E$8+0.0 | B18: =(((1+('Segment Revenue Build'!$E$7/'Segment Revenue Build'!$E$19)*((A18-Assumptions!$E$8)/(1+Assumptions!$E$8)))*'DCF Valuation'!$E$23/(1+'DCF Valuation'!$E$15)^1+(1+('Segment Revenue Build'!$E$7/'Segment Revenue Build'!$E$19)*((A18-Assumptions!$E$8)/(1+Assumptions!$E$8)))*'DCF Valuation'!$F$23/(1+'DCF Valuation'!$E$15)^2+(1+('Segment Revenue Build'!$E$7/'Segment Revenue Build'!$E$19)*((A18-Assumptions!$E$8)/(1+Assumptions!$E$8)))*'DCF Valuation'!$G$23/(1+'DCF Valuation'!$E$15)^3+((1+('Segment Revenue Build'!$E$7/'Segment Revenue Build'!$E$19)*((A18-Assumptions!$E$8)/(1+Assumptions!$E$8)))*'DCF Valuation'!$G$23*(1+'DCF Valuation'!$E$16)/('DCF Valuation'!$E$15-'DCF Valuation'!$E$16))/(1+'DCF Valuation'!$E$15)^3)-'DCF Valuation'!$E$33)/'DCF Valuation'!$E$35
A19: =Assumptions!$E$8+0.05 | B19: =(((1+('Segment Revenue Build'!$E$7/'Segment Revenue Build'!$E$19)*((A19-Assumptions!$E$8)/(1+Assumptions!$E$8)))*'DCF Valuation'!$E$23/(1+'DCF Valuation'!$E$15)^1+(1+('Segment Revenue Build'!$E$7/'Segment Revenue Build'!$E$19)*((A19-Assumptions!$E$8)/(1+Assumptions!$E$8)))*'DCF Valuation'!$F$23/(1+'DCF Valuation'!$E$15)^2+(1+('Segment Revenue Build'!$E$7/'Segment Revenue Build'!$E$19)*((A19-Assumptions!$E$8)/(1+Assumptions!$E$8)))*'DCF Valuation'!$G$23/(1+'DCF Valuation'!$E$15)^3+((1+('Segment Revenue Build'!$E$7/'Segment Revenue Build'!$E$19)*((A19-Assumptions!$E$8)/(1+Assumptions!$E$8)))*'DCF Valuation'!$G$23*(1+'DCF Valuation'!$E$16)/('DCF Valuation'!$E$15-'DCF Valuation'!$E$16))/(1+'DCF Valuation'!$E$15)^3)-'DCF Valuation'!$E$33)/'DCF Valuation'!$E$35
A20: =Assumptions!$E$8+0.1 | B20: =(((1+('Segment Revenue Build'!$E$7/'Segment Revenue Build'!$E$19)*((A20-Assumptions!$E$8)/(1+Assumptions!$E$8)))*'DCF Valuation'!$E$23/(1+'DCF Valuation'!$E$15)^1+(1+('Segment Revenue Build'!$E$7/'Segment Revenue Build'!$E$19)*((A20-Assumptions!$E$8)/(1+Assumptions!$E$8)))*'DCF Valuation'!$F$23/(1+'DCF Valuation'!$E$15)^2+(1+('Segment Revenue Build'!$E$7/'Segment Revenue Build'!$E$19)*((A20-Assumptions!$E$8)/(1+Assumptions!$E$8)))*'DCF Valuation'!$G$23/(1+'DCF Valuation'!$E$15)^3+((1+('Segment Revenue Build'!$E$7/'Segment Revenue Build'!$E$19)*((A20-Assumptions!$E$8)/(1+Assumptions!$E$8)))*'DCF Valuation'!$G$23*(1+'DCF Valuation'!$E$16)/('DCF Valuation'!$E$15-'DCF Valuation'!$E$16))/(1+'DCF Valuation'!$E$15)^3)-'DCF Valuation'!$E$33)/'DCF Valuation'!$E$35
A21: =Assumptions!$E$8+0.15 | B21: =(((1+('Segment Revenue Build'!$E$7/'Segment Revenue Build'!$E$19)*((A21-Assumptions!$E$8)/(1+Assumptions!$E$8)))*'DCF Valuation'!$E$23/(1+'DCF Valuation'!$E$15)^1+(1+('Segment Revenue Build'!$E$7/'Segment Revenue Build'!$E$19)*((A21-Assumptions!$E$8)/(1+Assumptions!$E$8)))*'DCF Valuation'!$F$23/(1+'DCF Valuation'!$E$15)^2+(1+('Segment Revenue Build'!$E$7/'Segment Revenue Build'!$E$19)*((A21-Assumptions!$E$8)/(1+Assumptions!$E$8)))*'DCF Valuation'!$G$23/(1+'DCF Valuation'!$E$15)^3+((1+('Segment Revenue Build'!$E$7/'Segment Revenue Build'!$E$19)*((A21-Assumptions!$E$8)/(1+Assumptions!$E$8)))*'DCF Valuation'!$G$23*(1+'DCF Valuation'!$E$16)/('DCF Valuation'!$E$15-'DCF Valuation'!$E$16))/(1+'DCF Valuation'!$E$15)^3)-'DCF Valuation'!$E$33)/'DCF Valuation'!$E$35
